[Wed Jul 21 08:39:57.022890 2021] [wsgi:error] [pid 6854:tid 140150092584704] [remote 109.65.245.83:58092] Not Found: /favicon.ico
[Wed Jul 21 09:15:57.889289 2021] [wsgi:error] [pid 6854:tid 140150092584704] [remote 209.141.50.63:48152] Not Found: /boaform/admin/formLogin
[Wed Jul 21 13:11:31.547562 2021] [wsgi:error] [pid 6854:tid 140150210180864] [remote 109.65.245.83:54731] Not Found: /test
[Wed Jul 21 13:11:55.539795 2021] [wsgi:error] [pid 6854:tid 140150210180864] [remote 109.65.245.83:55786] Not Found: /tests/
[Wed Jul 21 13:15:43.453766 2021] [wsgi:error] [pid 6854:tid 140150092584704] [remote 109.65.245.83:64404] Not Found: /tests/
[Wed Jul 21 13:16:33.779053 2021] [wsgi:error] [pid 6854:tid 140150210180864] [remote 109.65.245.83:54717] Not Found: /create_test
[Wed Jul 21 13:24:02.911053 2021] [wsgi:error] [pid 6854:tid 140150092584704] [remote 109.65.245.83:55466] Not Found: /create_test
[Wed Jul 21 13:27:15.799589 2021] [wsgi:error] [pid 6854:tid 140150210180864] [remote 109.65.245.83:65436] Not Found: /tests/
[Wed Jul 21 13:46:19.731246 2021] [wsgi:error] [pid 6854:tid 140150210180864] [remote 109.65.245.83:60102] Not Found: /tests/
[Wed Jul 21 13:46:32.395327 2021] [wsgi:error] [pid 6854:tid 140150210180864] [remote 109.65.245.83:49658] Not Found: /instance
[Wed Jul 21 13:48:49.373037 2021] [wsgi:error] [pid 6854:tid 140150092584704] [remote 109.65.245.83:60796] Not Found: /instance
[Wed Jul 21 13:49:07.846666 2021] [wsgi:error] [pid 6854:tid 140150210180864] [remote 109.65.245.83:55818] Not Found: /tests
[Wed Jul 21 13:49:25.205813 2021] [wsgi:error] [pid 6854:tid 140150210180864] [remote 109.65.245.83:57208] Not Found: /admin/tests
[Wed Jul 21 13:50:26.773685 2021] [wsgi:error] [pid 6854:tid 140150092584704] [remote 109.65.245.83:55505] Not Found: /tests
[Wed Jul 21 13:53:47.701863 2021] [wsgi:error] [pid 6854:tid 140150210180864] [remote 109.65.245.83:54370] Not Found: /tests
[Wed Jul 21 13:57:21.798002 2021] [wsgi:error] [pid 6854:tid 140150092584704] [remote 109.65.245.83:61618] Not Found: /tests
Exception ignored in: <function BaseEventLoop.__del__ at 0x7f773b824a60>
Traceback (most recent call last):
  File "/usr/lib/python3.7/asyncio/base_events.py", line 622, in __del__
NameError: name 'ResourceWarning' is not defined
[Wed Jul 21 15:21:41.056490 2021] [wsgi:error] [pid 7231:tid 140373496321792] [remote 89.248.172.16:39040] Not Found: /robots.txt
[Wed Jul 21 15:21:41.375180 2021] [wsgi:error] [pid 7231:tid 140373613909760] [remote 89.248.172.16:39174] Not Found: /sitemap.xml
[Wed Jul 21 15:21:41.698959 2021] [wsgi:error] [pid 7231:tid 140373496321792] [remote 89.248.172.16:39274] Not Found: /.well-known/security.txt
[Wed Jul 21 15:21:43.006083 2021] [wsgi:error] [pid 7231:tid 140373613909760] [remote 89.248.172.16:39738] Not Found: /favicon.ico
[Wed Jul 21 16:12:00.813103 2021] [wsgi:error] [pid 7231:tid 140373613909760] [remote 34.208.176.216:39802] Invalid HTTP_HOST header: 'icanhazip.com:443'. You may need to add 'icanhazip.com' to ALLOWED_HOSTS.
[Wed Jul 21 16:12:00.840651 2021] [wsgi:error] [pid 7231:tid 140373613909760] [remote 34.208.176.216:39802] Bad Request: /
[Wed Jul 21 16:56:32.883203 2021] [wsgi:error] [pid 7231:tid 140373613909760] [remote 205.185.115.135:56246] Not Found: /boaform/admin/formLogin
[Wed Jul 21 16:58:30.483791 2021] [wsgi:error] [pid 7231:tid 140373496321792] [remote 147.182.179.243:50936] Not Found: /boaform/admin/formLogin
[Wed Jul 21 17:05:00.016118 2021] [wsgi:error] [pid 7231:tid 140373613909760] [remote 165.232.146.19:58276] Not Found: /boaform/admin/formLogin
[Wed Jul 21 18:03:21.269125 2021] [wsgi:error] [pid 7231:tid 140373613909760] [remote 147.182.179.241:33756] Not Found: /boaform/admin/formLogin
[Wed Jul 21 19:49:37.635201 2021] [wsgi:error] [pid 7231:tid 140373613909760] [remote 45.146.164.110:33488] Not Found: /vendor/phpunit/phpunit/src/Util/PHP/eval-stdin.php
[Wed Jul 21 19:49:37.636583 2021] [wsgi:error] [pid 7231:tid 140373496321792] [remote 45.146.164.110:33474] Not Found: /api/jsonws/invoke
[Wed Jul 21 19:49:37.734034 2021] [wsgi:error] [pid 7231:tid 140373513123584] [remote 45.146.164.110:44342] Not Found: /solr/admin/info/system
[Wed Jul 21 19:49:37.737939 2021] [wsgi:error] [pid 7231:tid 140373496321792] [remote 45.146.164.110:44318] Not Found: /vendor/phpunit/phpunit/src/Util/PHP/eval-stdin.php
[Wed Jul 21 19:49:37.832906 2021] [wsgi:error] [pid 7231:tid 140373496321792] [remote 45.146.164.110:55002] Not Found: /wp-content/plugins/wp-file-manager/readme.txt
[Wed Jul 21 19:49:37.925730 2021] [wsgi:error] [pid 7231:tid 140373513123584] [remote 45.146.164.110:36696] Not Found: /index.php
[Wed Jul 21 19:49:38.058540 2021] [wsgi:error] [pid 7231:tid 140373613909760] [remote 45.146.164.110:48300] Not Found: /console/
[Wed Jul 21 19:49:38.390415 2021] [wsgi:error] [pid 7231:tid 140373513123584] [remote 45.146.164.110:56524] Not Found: /_ignition/execute-solution
[Wed Jul 21 19:49:39.153559 2021] [wsgi:error] [pid 7231:tid 140373613909760] [remote 45.146.164.110:60206] Not Found: /Autodiscover/Autodiscover.xml
[Wed Jul 21 20:03:07.204076 2021] [wsgi:error] [pid 7231:tid 140373513123584] [remote 120.85.118.136:24987] Invalid HTTP_HOST header: '127.0.0.1:80'. You may need to add '127.0.0.1' to ALLOWED_HOSTS.
[Wed Jul 21 20:03:07.229798 2021] [wsgi:error] [pid 7231:tid 140373513123584] [remote 120.85.118.136:24987] Bad Request: /GponForm/diag_Form
[Wed Jul 21 20:35:47.380594 2021] [wsgi:error] [pid 7231:tid 140373513123584] [remote 45.9.110.186:13296] Not Found: /favicon.ico
[Wed Jul 21 21:33:23.375976 2021] [wsgi:error] [pid 7231:tid 140373513123584] [remote 205.185.115.135:56306] Not Found: /boaform/admin/formLogin
[Wed Jul 21 22:08:54.349241 2021] [wsgi:error] [pid 7231:tid 140373613909760] [remote 92.222.171.18:57086] Not Found: /manager/html
[Wed Jul 21 23:09:45.445031 2021] [wsgi:error] [pid 7231:tid 140373613909760] [remote 209.90.225.218:57075] Invalid HTTP_HOST header: 'web-dev.c.mbexam-4.internal'. You may need to add 'web-dev.c.mbexam-4.internal' to ALLOWED_HOSTS.
[Wed Jul 21 23:09:45.471313 2021] [wsgi:error] [pid 7231:tid 140373613909760] [remote 209.90.225.218:57075] Bad Request: /robots.txt
[Wed Jul 21 23:10:38.035233 2021] [wsgi:error] [pid 7231:tid 140373513123584] [remote 135.125.217.54:55614] Forbidden (CSRF cookie not set.): /
[Wed Jul 21 23:10:38.083095 2021] [wsgi:error] [pid 7231:tid 140373613909760] [remote 135.125.217.54:55704] Not Found: /.env
[Wed Jul 21 23:48:52.310075 2021] [wsgi:error] [pid 7231:tid 140373513123584] [remote 209.141.54.8:37504] Not Found: /boaform/admin/formLogin
[Thu Jul 22 00:03:05.015583 2021] [wsgi:error] [pid 7231:tid 140373613909760] [remote 209.141.41.98:47088] Not Found: /boaform/admin/formLogin
[Thu Jul 22 00:06:34.703702 2021] [wsgi:error] [pid 7231:tid 140373513123584] [remote 209.17.96.210:65438] Invalid HTTP_HOST header: 'web-dev.c.mbexam-4.internal'. You may need to add 'web-dev.c.mbexam-4.internal' to ALLOWED_HOSTS.
[Thu Jul 22 00:06:34.729538 2021] [wsgi:error] [pid 7231:tid 140373513123584] [remote 209.17.96.210:65438] Bad Request: /
[Thu Jul 22 01:37:48.823300 2021] [wsgi:error] [pid 7231:tid 140373513123584] [remote 62.210.10.77:55331] Not Found: /favicon.ico
[Thu Jul 22 01:55:24.925384 2021] [wsgi:error] [pid 7231:tid 140373613909760] [remote 109.248.6.73:59312] Invalid HTTP_HOST header: 'localhost'. You may need to add 'localhost' to ALLOWED_HOSTS.
[Thu Jul 22 01:55:24.951856 2021] [wsgi:error] [pid 7231:tid 140373613909760] [remote 109.248.6.73:59312] Bad Request: /recv4.php
[Thu Jul 22 04:39:26.280992 2021] [wsgi:error] [pid 7231:tid 140373513123584] [remote 54.183.216.220:65260] Not Found: /.env
[Thu Jul 22 04:39:26.567002 2021] [wsgi:error] [pid 7231:tid 140373613909760] [remote 54.183.216.220:62003] Forbidden (CSRF cookie not set.): /
[Thu Jul 22 04:57:38.162615 2021] [wsgi:error] [pid 7231:tid 140373513123584] [remote 143.198.70.67:41140] Not Found: /boaform/admin/formLogin
[Thu Jul 22 06:36:58.847509 2021] [wsgi:error] [pid 7231:tid 140373513123584] [remote 205.185.115.135:59856] Not Found: /boaform/admin/formLogin
[Thu Jul 22 07:13:18.973850 2021] [wsgi:error] [pid 7231:tid 140373613909760] [remote 79.183.188.151:62392] Not Found: /favicon.ico
Exception ignored in: <function BaseEventLoop.__del__ at 0x7fab3f68aa60>
Traceback (most recent call last):
  File "/usr/lib/python3.7/asyncio/base_events.py", line 622, in __del__
NameError: name 'ResourceWarning' is not defined
[Thu Jul 22 07:17:13.329961 2021] [wsgi:error] [pid 9837:tid 139774469170944] [remote 79.183.188.151:59172] Internal Server Error: /create_test/
[Thu Jul 22 07:17:13.330012 2021] [wsgi:error] [pid 9837:tid 139774469170944] [remote 79.183.188.151:59172] Traceback (most recent call last):
[Thu Jul 22 07:17:13.330017 2021] [wsgi:error] [pid 9837:tid 139774469170944] [remote 79.183.188.151:59172]   File "/mazebolt_project/venv/lib/python3.7/site-packages/django/core/handlers/exception.py", line 47, in inner
[Thu Jul 22 07:17:13.330021 2021] [wsgi:error] [pid 9837:tid 139774469170944] [remote 79.183.188.151:59172]     response = get_response(request)
[Thu Jul 22 07:17:13.330025 2021] [wsgi:error] [pid 9837:tid 139774469170944] [remote 79.183.188.151:59172]   File "/mazebolt_project/venv/lib/python3.7/site-packages/django/core/handlers/base.py", line 181, in _get_response
[Thu Jul 22 07:17:13.330029 2021] [wsgi:error] [pid 9837:tid 139774469170944] [remote 79.183.188.151:59172]     response = wrapped_callback(request, *callback_args, **callback_kwargs)
[Thu Jul 22 07:17:13.330033 2021] [wsgi:error] [pid 9837:tid 139774469170944] [remote 79.183.188.151:59172]   File "/mazebolt_project/django/mazebolt_project/mazebolt_project/views.py", line 22, in create_test
[Thu Jul 22 07:17:13.330037 2021] [wsgi:error] [pid 9837:tid 139774469170944] [remote 79.183.188.151:59172]     return render(requset, 'create_test.html', selected_instances)
[Thu Jul 22 07:17:13.330041 2021] [wsgi:error] [pid 9837:tid 139774469170944] [remote 79.183.188.151:59172]   File "/mazebolt_project/venv/lib/python3.7/site-packages/django/shortcuts.py", line 19, in render
[Thu Jul 22 07:17:13.330045 2021] [wsgi:error] [pid 9837:tid 139774469170944] [remote 79.183.188.151:59172]     content = loader.render_to_string(template_name, context, request, using=using)
[Thu Jul 22 07:17:13.330049 2021] [wsgi:error] [pid 9837:tid 139774469170944] [remote 79.183.188.151:59172]   File "/mazebolt_project/venv/lib/python3.7/site-packages/django/template/loader.py", line 61, in render_to_string
[Thu Jul 22 07:17:13.330052 2021] [wsgi:error] [pid 9837:tid 139774469170944] [remote 79.183.188.151:59172]     template = get_template(template_name, using=using)
[Thu Jul 22 07:17:13.330056 2021] [wsgi:error] [pid 9837:tid 139774469170944] [remote 79.183.188.151:59172]   File "/mazebolt_project/venv/lib/python3.7/site-packages/django/template/loader.py", line 19, in get_template
[Thu Jul 22 07:17:13.330060 2021] [wsgi:error] [pid 9837:tid 139774469170944] [remote 79.183.188.151:59172]     raise TemplateDoesNotExist(template_name, chain=chain)
[Thu Jul 22 07:17:13.330064 2021] [wsgi:error] [pid 9837:tid 139774469170944] [remote 79.183.188.151:59172] django.template.exceptions.TemplateDoesNotExist: create_test.html
[Thu Jul 22 07:17:34.781865 2021] [wsgi:error] [pid 9837:tid 139774385153792] [remote 79.183.188.151:64151] Internal Server Error: /
[Thu Jul 22 07:17:34.781953 2021] [wsgi:error] [pid 9837:tid 139774385153792] [remote 79.183.188.151:64151] Traceback (most recent call last):
[Thu Jul 22 07:17:34.781957 2021] [wsgi:error] [pid 9837:tid 139774385153792] [remote 79.183.188.151:64151]   File "/mazebolt_project/venv/lib/python3.7/site-packages/django/core/handlers/exception.py", line 47, in inner
[Thu Jul 22 07:17:34.781962 2021] [wsgi:error] [pid 9837:tid 139774385153792] [remote 79.183.188.151:64151]     response = get_response(request)
[Thu Jul 22 07:17:34.781966 2021] [wsgi:error] [pid 9837:tid 139774385153792] [remote 79.183.188.151:64151]   File "/mazebolt_project/venv/lib/python3.7/site-packages/django/core/handlers/base.py", line 181, in _get_response
[Thu Jul 22 07:17:34.781970 2021] [wsgi:error] [pid 9837:tid 139774385153792] [remote 79.183.188.151:64151]     response = wrapped_callback(request, *callback_args, **callback_kwargs)
[Thu Jul 22 07:17:34.782011 2021] [wsgi:error] [pid 9837:tid 139774385153792] [remote 79.183.188.151:64151]   File "/mazebolt_project/django/mazebolt_project/mazebolt_project/views.py", line 10, in instance
[Thu Jul 22 07:17:34.782015 2021] [wsgi:error] [pid 9837:tid 139774385153792] [remote 79.183.188.151:64151]     return render(requset, 'instances.html', context)
[Thu Jul 22 07:17:34.782018 2021] [wsgi:error] [pid 9837:tid 139774385153792] [remote 79.183.188.151:64151]   File "/mazebolt_project/venv/lib/python3.7/site-packages/django/shortcuts.py", line 19, in render
[Thu Jul 22 07:17:34.782021 2021] [wsgi:error] [pid 9837:tid 139774385153792] [remote 79.183.188.151:64151]     content = loader.render_to_string(template_name, context, request, using=using)
[Thu Jul 22 07:17:34.782025 2021] [wsgi:error] [pid 9837:tid 139774385153792] [remote 79.183.188.151:64151]   File "/mazebolt_project/venv/lib/python3.7/site-packages/django/template/loader.py", line 61, in render_to_string
[Thu Jul 22 07:17:34.782028 2021] [wsgi:error] [pid 9837:tid 139774385153792] [remote 79.183.188.151:64151]     template = get_template(template_name, using=using)
[Thu Jul 22 07:17:34.782031 2021] [wsgi:error] [pid 9837:tid 139774385153792] [remote 79.183.188.151:64151]   File "/mazebolt_project/venv/lib/python3.7/site-packages/django/template/loader.py", line 19, in get_template
[Thu Jul 22 07:17:34.782035 2021] [wsgi:error] [pid 9837:tid 139774385153792] [remote 79.183.188.151:64151]     raise TemplateDoesNotExist(template_name, chain=chain)
[Thu Jul 22 07:17:34.782038 2021] [wsgi:error] [pid 9837:tid 139774385153792] [remote 79.183.188.151:64151] django.template.exceptions.TemplateDoesNotExist: instances.html
Exception ignored in: <function BaseEventLoop.__del__ at 0x7f1fc199ba60>
Traceback (most recent call last):
  File "/usr/lib/python3.7/asyncio/base_events.py", line 622, in __del__
NameError: name 'ResourceWarning' is not defined
[Thu Jul 22 07:30:26.712447 2021] [wsgi:error] [pid 9933:tid 140395226736384] [remote 79.183.188.151:54664] mod_wsgi (pid=9933): Failed to exec Python script file '/mazebolt_project/django/mazebolt_project/mazebolt_project/wsgi.py'.
[Thu Jul 22 07:30:26.712547 2021] [wsgi:error] [pid 9933:tid 140395226736384] [remote 79.183.188.151:54664] mod_wsgi (pid=9933): Exception occurred processing WSGI script '/mazebolt_project/django/mazebolt_project/mazebolt_project/wsgi.py'.
[Thu Jul 22 07:30:26.716395 2021] [wsgi:error] [pid 9933:tid 140395226736384] [remote 79.183.188.151:54664] Traceback (most recent call last):
[Thu Jul 22 07:30:26.716490 2021] [wsgi:error] [pid 9933:tid 140395226736384] [remote 79.183.188.151:54664]   File "/mazebolt_project/django/mazebolt_project/mazebolt_project/wsgi.py", line 16, in <module>
[Thu Jul 22 07:30:26.716497 2021] [wsgi:error] [pid 9933:tid 140395226736384] [remote 79.183.188.151:54664]     application = get_wsgi_application()
[Thu Jul 22 07:30:26.716503 2021] [wsgi:error] [pid 9933:tid 140395226736384] [remote 79.183.188.151:54664]   File "/mazebolt_project/venv/lib/python3.7/site-packages/django/core/wsgi.py", line 12, in get_wsgi_application
[Thu Jul 22 07:30:26.716508 2021] [wsgi:error] [pid 9933:tid 140395226736384] [remote 79.183.188.151:54664]     django.setup(set_prefix=False)
[Thu Jul 22 07:30:26.716513 2021] [wsgi:error] [pid 9933:tid 140395226736384] [remote 79.183.188.151:54664]   File "/mazebolt_project/venv/lib/python3.7/site-packages/django/__init__.py", line 19, in setup
[Thu Jul 22 07:30:26.716518 2021] [wsgi:error] [pid 9933:tid 140395226736384] [remote 79.183.188.151:54664]     configure_logging(settings.LOGGING_CONFIG, settings.LOGGING)
[Thu Jul 22 07:30:26.716523 2021] [wsgi:error] [pid 9933:tid 140395226736384] [remote 79.183.188.151:54664]   File "/mazebolt_project/venv/lib/python3.7/site-packages/django/conf/__init__.py", line 82, in __getattr__
[Thu Jul 22 07:30:26.716527 2021] [wsgi:error] [pid 9933:tid 140395226736384] [remote 79.183.188.151:54664]     self._setup(name)
[Thu Jul 22 07:30:26.716532 2021] [wsgi:error] [pid 9933:tid 140395226736384] [remote 79.183.188.151:54664]   File "/mazebolt_project/venv/lib/python3.7/site-packages/django/conf/__init__.py", line 69, in _setup
[Thu Jul 22 07:30:26.716573 2021] [wsgi:error] [pid 9933:tid 140395226736384] [remote 79.183.188.151:54664]     self._wrapped = Settings(settings_module)
[Thu Jul 22 07:30:26.716579 2021] [wsgi:error] [pid 9933:tid 140395226736384] [remote 79.183.188.151:54664]   File "/mazebolt_project/venv/lib/python3.7/site-packages/django/conf/__init__.py", line 170, in __init__
[Thu Jul 22 07:30:26.716583 2021] [wsgi:error] [pid 9933:tid 140395226736384] [remote 79.183.188.151:54664]     mod = importlib.import_module(self.SETTINGS_MODULE)
[Thu Jul 22 07:30:26.716588 2021] [wsgi:error] [pid 9933:tid 140395226736384] [remote 79.183.188.151:54664]   File "/usr/lib/python3.7/importlib/__init__.py", line 127, in import_module
[Thu Jul 22 07:30:26.716591 2021] [wsgi:error] [pid 9933:tid 140395226736384] [remote 79.183.188.151:54664]     return _bootstrap._gcd_import(name[level:], package, level)
[Thu Jul 22 07:30:26.716596 2021] [wsgi:error] [pid 9933:tid 140395226736384] [remote 79.183.188.151:54664]   File "<frozen importlib._bootstrap>", line 1006, in _gcd_import
[Thu Jul 22 07:30:26.716601 2021] [wsgi:error] [pid 9933:tid 140395226736384] [remote 79.183.188.151:54664]   File "<frozen importlib._bootstrap>", line 983, in _find_and_load
[Thu Jul 22 07:30:26.716606 2021] [wsgi:error] [pid 9933:tid 140395226736384] [remote 79.183.188.151:54664]   File "<frozen importlib._bootstrap>", line 967, in _find_and_load_unlocked
[Thu Jul 22 07:30:26.716611 2021] [wsgi:error] [pid 9933:tid 140395226736384] [remote 79.183.188.151:54664]   File "<frozen importlib._bootstrap>", line 677, in _load_unlocked
[Thu Jul 22 07:30:26.716616 2021] [wsgi:error] [pid 9933:tid 140395226736384] [remote 79.183.188.151:54664]   File "<frozen importlib._bootstrap_external>", line 728, in exec_module
[Thu Jul 22 07:30:26.716620 2021] [wsgi:error] [pid 9933:tid 140395226736384] [remote 79.183.188.151:54664]   File "<frozen importlib._bootstrap>", line 219, in _call_with_frames_removed
[Thu Jul 22 07:30:26.716626 2021] [wsgi:error] [pid 9933:tid 140395226736384] [remote 79.183.188.151:54664]   File "/mazebolt_project/django/mazebolt_project/mazebolt_project/settings.py", line 58, in <module>
[Thu Jul 22 07:30:26.716629 2021] [wsgi:error] [pid 9933:tid 140395226736384] [remote 79.183.188.151:54664]     'DIRS': [os.path.join(BASE_DIR, 'templates')],
[Thu Jul 22 07:30:26.716646 2021] [wsgi:error] [pid 9933:tid 140395226736384] [remote 79.183.188.151:54664] NameError: name 'os' is not defined
[Thu Jul 22 07:32:15.355981 2021] [wsgi:error] [pid 9933:tid 140395218335488] [remote 79.183.188.151:53750] mod_wsgi (pid=9933): Failed to exec Python script file '/mazebolt_project/django/mazebolt_project/mazebolt_project/wsgi.py'.
[Thu Jul 22 07:32:15.356060 2021] [wsgi:error] [pid 9933:tid 140395218335488] [remote 79.183.188.151:53750] mod_wsgi (pid=9933): Exception occurred processing WSGI script '/mazebolt_project/django/mazebolt_project/mazebolt_project/wsgi.py'.
[Thu Jul 22 07:32:15.356214 2021] [wsgi:error] [pid 9933:tid 140395218335488] [remote 79.183.188.151:53750] Traceback (most recent call last):
[Thu Jul 22 07:32:15.356330 2021] [wsgi:error] [pid 9933:tid 140395218335488] [remote 79.183.188.151:53750]   File "/mazebolt_project/django/mazebolt_project/mazebolt_project/wsgi.py", line 16, in <module>
[Thu Jul 22 07:32:15.356343 2021] [wsgi:error] [pid 9933:tid 140395218335488] [remote 79.183.188.151:53750]     application = get_wsgi_application()
[Thu Jul 22 07:32:15.356355 2021] [wsgi:error] [pid 9933:tid 140395218335488] [remote 79.183.188.151:53750]   File "/mazebolt_project/venv/lib/python3.7/site-packages/django/core/wsgi.py", line 12, in get_wsgi_application
[Thu Jul 22 07:32:15.356363 2021] [wsgi:error] [pid 9933:tid 140395218335488] [remote 79.183.188.151:53750]     django.setup(set_prefix=False)
[Thu Jul 22 07:32:15.356375 2021] [wsgi:error] [pid 9933:tid 140395218335488] [remote 79.183.188.151:53750]   File "/mazebolt_project/venv/lib/python3.7/site-packages/django/__init__.py", line 19, in setup
[Thu Jul 22 07:32:15.356400 2021] [wsgi:error] [pid 9933:tid 140395218335488] [remote 79.183.188.151:53750]     configure_logging(settings.LOGGING_CONFIG, settings.LOGGING)
[Thu Jul 22 07:32:15.356407 2021] [wsgi:error] [pid 9933:tid 140395218335488] [remote 79.183.188.151:53750]   File "/mazebolt_project/venv/lib/python3.7/site-packages/django/conf/__init__.py", line 82, in __getattr__
[Thu Jul 22 07:32:15.356412 2021] [wsgi:error] [pid 9933:tid 140395218335488] [remote 79.183.188.151:53750]     self._setup(name)
[Thu Jul 22 07:32:15.356418 2021] [wsgi:error] [pid 9933:tid 140395218335488] [remote 79.183.188.151:53750]   File "/mazebolt_project/venv/lib/python3.7/site-packages/django/conf/__init__.py", line 69, in _setup
[Thu Jul 22 07:32:15.356423 2021] [wsgi:error] [pid 9933:tid 140395218335488] [remote 79.183.188.151:53750]     self._wrapped = Settings(settings_module)
[Thu Jul 22 07:32:15.356430 2021] [wsgi:error] [pid 9933:tid 140395218335488] [remote 79.183.188.151:53750]   File "/mazebolt_project/venv/lib/python3.7/site-packages/django/conf/__init__.py", line 170, in __init__
[Thu Jul 22 07:32:15.356435 2021] [wsgi:error] [pid 9933:tid 140395218335488] [remote 79.183.188.151:53750]     mod = importlib.import_module(self.SETTINGS_MODULE)
[Thu Jul 22 07:32:15.356441 2021] [wsgi:error] [pid 9933:tid 140395218335488] [remote 79.183.188.151:53750]   File "/usr/lib/python3.7/importlib/__init__.py", line 127, in import_module
[Thu Jul 22 07:32:15.356446 2021] [wsgi:error] [pid 9933:tid 140395218335488] [remote 79.183.188.151:53750]     return _bootstrap._gcd_import(name[level:], package, level)
[Thu Jul 22 07:32:15.356452 2021] [wsgi:error] [pid 9933:tid 140395218335488] [remote 79.183.188.151:53750]   File "<frozen importlib._bootstrap>", line 1006, in _gcd_import
[Thu Jul 22 07:32:15.356459 2021] [wsgi:error] [pid 9933:tid 140395218335488] [remote 79.183.188.151:53750]   File "<frozen importlib._bootstrap>", line 983, in _find_and_load
[Thu Jul 22 07:32:15.356466 2021] [wsgi:error] [pid 9933:tid 140395218335488] [remote 79.183.188.151:53750]   File "<frozen importlib._bootstrap>", line 967, in _find_and_load_unlocked
[Thu Jul 22 07:32:15.356474 2021] [wsgi:error] [pid 9933:tid 140395218335488] [remote 79.183.188.151:53750]   File "<frozen importlib._bootstrap>", line 677, in _load_unlocked
[Thu Jul 22 07:32:15.356481 2021] [wsgi:error] [pid 9933:tid 140395218335488] [remote 79.183.188.151:53750]   File "<frozen importlib._bootstrap_external>", line 728, in exec_module
[Thu Jul 22 07:32:15.356488 2021] [wsgi:error] [pid 9933:tid 140395218335488] [remote 79.183.188.151:53750]   File "<frozen importlib._bootstrap>", line 219, in _call_with_frames_removed
[Thu Jul 22 07:32:15.356495 2021] [wsgi:error] [pid 9933:tid 140395218335488] [remote 79.183.188.151:53750]   File "/mazebolt_project/django/mazebolt_project/mazebolt_project/settings.py", line 58, in <module>
[Thu Jul 22 07:32:15.356500 2021] [wsgi:error] [pid 9933:tid 140395218335488] [remote 79.183.188.151:53750]     'DIRS': [os.path.join(BASE_DIR, 'templates')],
[Thu Jul 22 07:32:15.356519 2021] [wsgi:error] [pid 9933:tid 140395218335488] [remote 79.183.188.151:53750] NameError: name 'os' is not defined
[Thu Jul 22 07:32:18.515579 2021] [wsgi:error] [pid 9933:tid 140395226736384] [remote 79.183.188.151:60178] mod_wsgi (pid=9933): Failed to exec Python script file '/mazebolt_project/django/mazebolt_project/mazebolt_project/wsgi.py'.
[Thu Jul 22 07:32:18.515632 2021] [wsgi:error] [pid 9933:tid 140395226736384] [remote 79.183.188.151:60178] mod_wsgi (pid=9933): Exception occurred processing WSGI script '/mazebolt_project/django/mazebolt_project/mazebolt_project/wsgi.py'.
[Thu Jul 22 07:32:18.515768 2021] [wsgi:error] [pid 9933:tid 140395226736384] [remote 79.183.188.151:60178] Traceback (most recent call last):
[Thu Jul 22 07:32:18.515812 2021] [wsgi:error] [pid 9933:tid 140395226736384] [remote 79.183.188.151:60178]   File "/mazebolt_project/django/mazebolt_project/mazebolt_project/wsgi.py", line 16, in <module>
[Thu Jul 22 07:32:18.515836 2021] [wsgi:error] [pid 9933:tid 140395226736384] [remote 79.183.188.151:60178]     application = get_wsgi_application()
[Thu Jul 22 07:32:18.515842 2021] [wsgi:error] [pid 9933:tid 140395226736384] [remote 79.183.188.151:60178]   File "/mazebolt_project/venv/lib/python3.7/site-packages/django/core/wsgi.py", line 12, in get_wsgi_application
[Thu Jul 22 07:32:18.515846 2021] [wsgi:error] [pid 9933:tid 140395226736384] [remote 79.183.188.151:60178]     django.setup(set_prefix=False)
[Thu Jul 22 07:32:18.515851 2021] [wsgi:error] [pid 9933:tid 140395226736384] [remote 79.183.188.151:60178]   File "/mazebolt_project/venv/lib/python3.7/site-packages/django/__init__.py", line 19, in setup
[Thu Jul 22 07:32:18.515855 2021] [wsgi:error] [pid 9933:tid 140395226736384] [remote 79.183.188.151:60178]     configure_logging(settings.LOGGING_CONFIG, settings.LOGGING)
[Thu Jul 22 07:32:18.515859 2021] [wsgi:error] [pid 9933:tid 140395226736384] [remote 79.183.188.151:60178]   File "/mazebolt_project/venv/lib/python3.7/site-packages/django/conf/__init__.py", line 82, in __getattr__
[Thu Jul 22 07:32:18.515863 2021] [wsgi:error] [pid 9933:tid 140395226736384] [remote 79.183.188.151:60178]     self._setup(name)
[Thu Jul 22 07:32:18.515868 2021] [wsgi:error] [pid 9933:tid 140395226736384] [remote 79.183.188.151:60178]   File "/mazebolt_project/venv/lib/python3.7/site-packages/django/conf/__init__.py", line 69, in _setup
[Thu Jul 22 07:32:18.515872 2021] [wsgi:error] [pid 9933:tid 140395226736384] [remote 79.183.188.151:60178]     self._wrapped = Settings(settings_module)
[Thu Jul 22 07:32:18.515876 2021] [wsgi:error] [pid 9933:tid 140395226736384] [remote 79.183.188.151:60178]   File "/mazebolt_project/venv/lib/python3.7/site-packages/django/conf/__init__.py", line 170, in __init__
[Thu Jul 22 07:32:18.515880 2021] [wsgi:error] [pid 9933:tid 140395226736384] [remote 79.183.188.151:60178]     mod = importlib.import_module(self.SETTINGS_MODULE)
[Thu Jul 22 07:32:18.515885 2021] [wsgi:error] [pid 9933:tid 140395226736384] [remote 79.183.188.151:60178]   File "/usr/lib/python3.7/importlib/__init__.py", line 127, in import_module
[Thu Jul 22 07:32:18.515888 2021] [wsgi:error] [pid 9933:tid 140395226736384] [remote 79.183.188.151:60178]     return _bootstrap._gcd_import(name[level:], package, level)
[Thu Jul 22 07:32:18.515893 2021] [wsgi:error] [pid 9933:tid 140395226736384] [remote 79.183.188.151:60178]   File "<frozen importlib._bootstrap>", line 1006, in _gcd_import
[Thu Jul 22 07:32:18.515898 2021] [wsgi:error] [pid 9933:tid 140395226736384] [remote 79.183.188.151:60178]   File "<frozen importlib._bootstrap>", line 983, in _find_and_load
[Thu Jul 22 07:32:18.515903 2021] [wsgi:error] [pid 9933:tid 140395226736384] [remote 79.183.188.151:60178]   File "<frozen importlib._bootstrap>", line 967, in _find_and_load_unlocked
[Thu Jul 22 07:32:18.515908 2021] [wsgi:error] [pid 9933:tid 140395226736384] [remote 79.183.188.151:60178]   File "<frozen importlib._bootstrap>", line 677, in _load_unlocked
[Thu Jul 22 07:32:18.515912 2021] [wsgi:error] [pid 9933:tid 140395226736384] [remote 79.183.188.151:60178]   File "<frozen importlib._bootstrap_external>", line 728, in exec_module
[Thu Jul 22 07:32:18.515917 2021] [wsgi:error] [pid 9933:tid 140395226736384] [remote 79.183.188.151:60178]   File "<frozen importlib._bootstrap>", line 219, in _call_with_frames_removed
[Thu Jul 22 07:32:18.515922 2021] [wsgi:error] [pid 9933:tid 140395226736384] [remote 79.183.188.151:60178]   File "/mazebolt_project/django/mazebolt_project/mazebolt_project/settings.py", line 58, in <module>
[Thu Jul 22 07:32:18.515926 2021] [wsgi:error] [pid 9933:tid 140395226736384] [remote 79.183.188.151:60178]     'DIRS': [os.path.join(BASE_DIR, 'templates')],
[Thu Jul 22 07:32:18.515939 2021] [wsgi:error] [pid 9933:tid 140395226736384] [remote 79.183.188.151:60178] NameError: name 'os' is not defined
[Thu Jul 22 07:53:09.583756 2021] [wsgi:error] [pid 11102:tid 139959273891584] [remote 79.183.188.151:53850] mod_wsgi (pid=11102): Failed to exec Python script file '/mazebolt_project/django/mazebolt_project/mazebolt_project/wsgi.py'.
[Thu Jul 22 07:53:09.583872 2021] [wsgi:error] [pid 11102:tid 139959273891584] [remote 79.183.188.151:53850] mod_wsgi (pid=11102): Exception occurred processing WSGI script '/mazebolt_project/django/mazebolt_project/mazebolt_project/wsgi.py'.
[Thu Jul 22 07:53:09.584423 2021] [wsgi:error] [pid 11102:tid 139959273891584] [remote 79.183.188.151:53850] Traceback (most recent call last):
[Thu Jul 22 07:53:09.584477 2021] [wsgi:error] [pid 11102:tid 139959273891584] [remote 79.183.188.151:53850]   File "/mazebolt_project/django/mazebolt_project/mazebolt_project/wsgi.py", line 16, in <module>
[Thu Jul 22 07:53:09.584482 2021] [wsgi:error] [pid 11102:tid 139959273891584] [remote 79.183.188.151:53850]     application = get_wsgi_application()
[Thu Jul 22 07:53:09.584488 2021] [wsgi:error] [pid 11102:tid 139959273891584] [remote 79.183.188.151:53850]   File "/mazebolt_project/venv/lib/python3.7/site-packages/django/core/wsgi.py", line 12, in get_wsgi_application
[Thu Jul 22 07:53:09.584492 2021] [wsgi:error] [pid 11102:tid 139959273891584] [remote 79.183.188.151:53850]     django.setup(set_prefix=False)
[Thu Jul 22 07:53:09.584497 2021] [wsgi:error] [pid 11102:tid 139959273891584] [remote 79.183.188.151:53850]   File "/mazebolt_project/venv/lib/python3.7/site-packages/django/__init__.py", line 19, in setup
[Thu Jul 22 07:53:09.584500 2021] [wsgi:error] [pid 11102:tid 139959273891584] [remote 79.183.188.151:53850]     configure_logging(settings.LOGGING_CONFIG, settings.LOGGING)
[Thu Jul 22 07:53:09.584505 2021] [wsgi:error] [pid 11102:tid 139959273891584] [remote 79.183.188.151:53850]   File "/mazebolt_project/venv/lib/python3.7/site-packages/django/conf/__init__.py", line 82, in __getattr__
[Thu Jul 22 07:53:09.584509 2021] [wsgi:error] [pid 11102:tid 139959273891584] [remote 79.183.188.151:53850]     self._setup(name)
[Thu Jul 22 07:53:09.584513 2021] [wsgi:error] [pid 11102:tid 139959273891584] [remote 79.183.188.151:53850]   File "/mazebolt_project/venv/lib/python3.7/site-packages/django/conf/__init__.py", line 69, in _setup
[Thu Jul 22 07:53:09.584517 2021] [wsgi:error] [pid 11102:tid 139959273891584] [remote 79.183.188.151:53850]     self._wrapped = Settings(settings_module)
[Thu Jul 22 07:53:09.584522 2021] [wsgi:error] [pid 11102:tid 139959273891584] [remote 79.183.188.151:53850]   File "/mazebolt_project/venv/lib/python3.7/site-packages/django/conf/__init__.py", line 170, in __init__
[Thu Jul 22 07:53:09.584525 2021] [wsgi:error] [pid 11102:tid 139959273891584] [remote 79.183.188.151:53850]     mod = importlib.import_module(self.SETTINGS_MODULE)
[Thu Jul 22 07:53:09.584530 2021] [wsgi:error] [pid 11102:tid 139959273891584] [remote 79.183.188.151:53850]   File "/usr/lib/python3.7/importlib/__init__.py", line 127, in import_module
[Thu Jul 22 07:53:09.584533 2021] [wsgi:error] [pid 11102:tid 139959273891584] [remote 79.183.188.151:53850]     return _bootstrap._gcd_import(name[level:], package, level)
[Thu Jul 22 07:53:09.584538 2021] [wsgi:error] [pid 11102:tid 139959273891584] [remote 79.183.188.151:53850]   File "<frozen importlib._bootstrap>", line 1006, in _gcd_import
[Thu Jul 22 07:53:09.584543 2021] [wsgi:error] [pid 11102:tid 139959273891584] [remote 79.183.188.151:53850]   File "<frozen importlib._bootstrap>", line 983, in _find_and_load
[Thu Jul 22 07:53:09.584548 2021] [wsgi:error] [pid 11102:tid 139959273891584] [remote 79.183.188.151:53850]   File "<frozen importlib._bootstrap>", line 967, in _find_and_load_unlocked
[Thu Jul 22 07:53:09.584553 2021] [wsgi:error] [pid 11102:tid 139959273891584] [remote 79.183.188.151:53850]   File "<frozen importlib._bootstrap>", line 677, in _load_unlocked
[Thu Jul 22 07:53:09.584558 2021] [wsgi:error] [pid 11102:tid 139959273891584] [remote 79.183.188.151:53850]   File "<frozen importlib._bootstrap_external>", line 728, in exec_module
[Thu Jul 22 07:53:09.584563 2021] [wsgi:error] [pid 11102:tid 139959273891584] [remote 79.183.188.151:53850]   File "<frozen importlib._bootstrap>", line 219, in _call_with_frames_removed
[Thu Jul 22 07:53:09.584585 2021] [wsgi:error] [pid 11102:tid 139959273891584] [remote 79.183.188.151:53850]   File "/mazebolt_project/django/mazebolt_project/mazebolt_project/settings.py", line 58, in <module>
[Thu Jul 22 07:53:09.584588 2021] [wsgi:error] [pid 11102:tid 139959273891584] [remote 79.183.188.151:53850]     'DIRS': [os.path.join(BASE_DIR, 'templates')],
[Thu Jul 22 07:53:09.584601 2021] [wsgi:error] [pid 11102:tid 139959273891584] [remote 79.183.188.151:53850] NameError: name 'os' is not defined
[Thu Jul 22 07:53:11.064767 2021] [wsgi:error] [pid 11102:tid 139959231887104] [remote 79.183.188.151:61132] mod_wsgi (pid=11102): Failed to exec Python script file '/mazebolt_project/django/mazebolt_project/mazebolt_project/wsgi.py'.
[Thu Jul 22 07:53:11.064839 2021] [wsgi:error] [pid 11102:tid 139959231887104] [remote 79.183.188.151:61132] mod_wsgi (pid=11102): Exception occurred processing WSGI script '/mazebolt_project/django/mazebolt_project/mazebolt_project/wsgi.py'.
[Thu Jul 22 07:53:11.064986 2021] [wsgi:error] [pid 11102:tid 139959231887104] [remote 79.183.188.151:61132] Traceback (most recent call last):
[Thu Jul 22 07:53:11.065037 2021] [wsgi:error] [pid 11102:tid 139959231887104] [remote 79.183.188.151:61132]   File "/mazebolt_project/django/mazebolt_project/mazebolt_project/wsgi.py", line 16, in <module>
[Thu Jul 22 07:53:11.065042 2021] [wsgi:error] [pid 11102:tid 139959231887104] [remote 79.183.188.151:61132]     application = get_wsgi_application()
[Thu Jul 22 07:53:11.065048 2021] [wsgi:error] [pid 11102:tid 139959231887104] [remote 79.183.188.151:61132]   File "/mazebolt_project/venv/lib/python3.7/site-packages/django/core/wsgi.py", line 12, in get_wsgi_application
[Thu Jul 22 07:53:11.065052 2021] [wsgi:error] [pid 11102:tid 139959231887104] [remote 79.183.188.151:61132]     django.setup(set_prefix=False)
[Thu Jul 22 07:53:11.065061 2021] [wsgi:error] [pid 11102:tid 139959231887104] [remote 79.183.188.151:61132]   File "/mazebolt_project/venv/lib/python3.7/site-packages/django/__init__.py", line 19, in setup
[Thu Jul 22 07:53:11.065065 2021] [wsgi:error] [pid 11102:tid 139959231887104] [remote 79.183.188.151:61132]     configure_logging(settings.LOGGING_CONFIG, settings.LOGGING)
[Thu Jul 22 07:53:11.065070 2021] [wsgi:error] [pid 11102:tid 139959231887104] [remote 79.183.188.151:61132]   File "/mazebolt_project/venv/lib/python3.7/site-packages/django/conf/__init__.py", line 82, in __getattr__
[Thu Jul 22 07:53:11.065074 2021] [wsgi:error] [pid 11102:tid 139959231887104] [remote 79.183.188.151:61132]     self._setup(name)
[Thu Jul 22 07:53:11.065079 2021] [wsgi:error] [pid 11102:tid 139959231887104] [remote 79.183.188.151:61132]   File "/mazebolt_project/venv/lib/python3.7/site-packages/django/conf/__init__.py", line 69, in _setup
[Thu Jul 22 07:53:11.065083 2021] [wsgi:error] [pid 11102:tid 139959231887104] [remote 79.183.188.151:61132]     self._wrapped = Settings(settings_module)
[Thu Jul 22 07:53:11.065088 2021] [wsgi:error] [pid 11102:tid 139959231887104] [remote 79.183.188.151:61132]   File "/mazebolt_project/venv/lib/python3.7/site-packages/django/conf/__init__.py", line 170, in __init__
[Thu Jul 22 07:53:11.065091 2021] [wsgi:error] [pid 11102:tid 139959231887104] [remote 79.183.188.151:61132]     mod = importlib.import_module(self.SETTINGS_MODULE)
[Thu Jul 22 07:53:11.065096 2021] [wsgi:error] [pid 11102:tid 139959231887104] [remote 79.183.188.151:61132]   File "/usr/lib/python3.7/importlib/__init__.py", line 127, in import_module
[Thu Jul 22 07:53:11.065100 2021] [wsgi:error] [pid 11102:tid 139959231887104] [remote 79.183.188.151:61132]     return _bootstrap._gcd_import(name[level:], package, level)
[Thu Jul 22 07:53:11.065105 2021] [wsgi:error] [pid 11102:tid 139959231887104] [remote 79.183.188.151:61132]   File "<frozen importlib._bootstrap>", line 1006, in _gcd_import
[Thu Jul 22 07:53:11.065110 2021] [wsgi:error] [pid 11102:tid 139959231887104] [remote 79.183.188.151:61132]   File "<frozen importlib._bootstrap>", line 983, in _find_and_load
[Thu Jul 22 07:53:11.065115 2021] [wsgi:error] [pid 11102:tid 139959231887104] [remote 79.183.188.151:61132]   File "<frozen importlib._bootstrap>", line 967, in _find_and_load_unlocked
[Thu Jul 22 07:53:11.065129 2021] [wsgi:error] [pid 11102:tid 139959231887104] [remote 79.183.188.151:61132]   File "<frozen importlib._bootstrap>", line 677, in _load_unlocked
[Thu Jul 22 07:53:11.065134 2021] [wsgi:error] [pid 11102:tid 139959231887104] [remote 79.183.188.151:61132]   File "<frozen importlib._bootstrap_external>", line 728, in exec_module
[Thu Jul 22 07:53:11.065139 2021] [wsgi:error] [pid 11102:tid 139959231887104] [remote 79.183.188.151:61132]   File "<frozen importlib._bootstrap>", line 219, in _call_with_frames_removed
[Thu Jul 22 07:53:11.065145 2021] [wsgi:error] [pid 11102:tid 139959231887104] [remote 79.183.188.151:61132]   File "/mazebolt_project/django/mazebolt_project/mazebolt_project/settings.py", line 58, in <module>
[Thu Jul 22 07:53:11.065148 2021] [wsgi:error] [pid 11102:tid 139959231887104] [remote 79.183.188.151:61132]     'DIRS': [os.path.join(BASE_DIR, 'templates')],
[Thu Jul 22 07:53:11.065161 2021] [wsgi:error] [pid 11102:tid 139959231887104] [remote 79.183.188.151:61132] NameError: name 'os' is not defined
[Thu Jul 22 07:53:11.972122 2021] [wsgi:error] [pid 11102:tid 139959273891584] [remote 79.183.188.151:58906] mod_wsgi (pid=11102): Failed to exec Python script file '/mazebolt_project/django/mazebolt_project/mazebolt_project/wsgi.py'.
[Thu Jul 22 07:53:11.972170 2021] [wsgi:error] [pid 11102:tid 139959273891584] [remote 79.183.188.151:58906] mod_wsgi (pid=11102): Exception occurred processing WSGI script '/mazebolt_project/django/mazebolt_project/mazebolt_project/wsgi.py'.
[Thu Jul 22 07:53:11.972355 2021] [wsgi:error] [pid 11102:tid 139959273891584] [remote 79.183.188.151:58906] Traceback (most recent call last):
[Thu Jul 22 07:53:11.972402 2021] [wsgi:error] [pid 11102:tid 139959273891584] [remote 79.183.188.151:58906]   File "/mazebolt_project/django/mazebolt_project/mazebolt_project/wsgi.py", line 16, in <module>
[Thu Jul 22 07:53:11.972407 2021] [wsgi:error] [pid 11102:tid 139959273891584] [remote 79.183.188.151:58906]     application = get_wsgi_application()
[Thu Jul 22 07:53:11.972412 2021] [wsgi:error] [pid 11102:tid 139959273891584] [remote 79.183.188.151:58906]   File "/mazebolt_project/venv/lib/python3.7/site-packages/django/core/wsgi.py", line 12, in get_wsgi_application
[Thu Jul 22 07:53:11.972416 2021] [wsgi:error] [pid 11102:tid 139959273891584] [remote 79.183.188.151:58906]     django.setup(set_prefix=False)
[Thu Jul 22 07:53:11.972421 2021] [wsgi:error] [pid 11102:tid 139959273891584] [remote 79.183.188.151:58906]   File "/mazebolt_project/venv/lib/python3.7/site-packages/django/__init__.py", line 19, in setup
[Thu Jul 22 07:53:11.972425 2021] [wsgi:error] [pid 11102:tid 139959273891584] [remote 79.183.188.151:58906]     configure_logging(settings.LOGGING_CONFIG, settings.LOGGING)
[Thu Jul 22 07:53:11.972430 2021] [wsgi:error] [pid 11102:tid 139959273891584] [remote 79.183.188.151:58906]   File "/mazebolt_project/venv/lib/python3.7/site-packages/django/conf/__init__.py", line 82, in __getattr__
[Thu Jul 22 07:53:11.972434 2021] [wsgi:error] [pid 11102:tid 139959273891584] [remote 79.183.188.151:58906]     self._setup(name)
[Thu Jul 22 07:53:11.972439 2021] [wsgi:error] [pid 11102:tid 139959273891584] [remote 79.183.188.151:58906]   File "/mazebolt_project/venv/lib/python3.7/site-packages/django/conf/__init__.py", line 69, in _setup
[Thu Jul 22 07:53:11.972442 2021] [wsgi:error] [pid 11102:tid 139959273891584] [remote 79.183.188.151:58906]     self._wrapped = Settings(settings_module)
[Thu Jul 22 07:53:11.972461 2021] [wsgi:error] [pid 11102:tid 139959273891584] [remote 79.183.188.151:58906]   File "/mazebolt_project/venv/lib/python3.7/site-packages/django/conf/__init__.py", line 170, in __init__
[Thu Jul 22 07:53:11.972465 2021] [wsgi:error] [pid 11102:tid 139959273891584] [remote 79.183.188.151:58906]     mod = importlib.import_module(self.SETTINGS_MODULE)
[Thu Jul 22 07:53:11.972470 2021] [wsgi:error] [pid 11102:tid 139959273891584] [remote 79.183.188.151:58906]   File "/usr/lib/python3.7/importlib/__init__.py", line 127, in import_module
[Thu Jul 22 07:53:11.972490 2021] [wsgi:error] [pid 11102:tid 139959273891584] [remote 79.183.188.151:58906]     return _bootstrap._gcd_import(name[level:], package, level)
[Thu Jul 22 07:53:11.972496 2021] [wsgi:error] [pid 11102:tid 139959273891584] [remote 79.183.188.151:58906]   File "<frozen importlib._bootstrap>", line 1006, in _gcd_import
[Thu Jul 22 07:53:11.972501 2021] [wsgi:error] [pid 11102:tid 139959273891584] [remote 79.183.188.151:58906]   File "<frozen importlib._bootstrap>", line 983, in _find_and_load
[Thu Jul 22 07:53:11.972505 2021] [wsgi:error] [pid 11102:tid 139959273891584] [remote 79.183.188.151:58906]   File "<frozen importlib._bootstrap>", line 967, in _find_and_load_unlocked
[Thu Jul 22 07:53:11.972510 2021] [wsgi:error] [pid 11102:tid 139959273891584] [remote 79.183.188.151:58906]   File "<frozen importlib._bootstrap>", line 677, in _load_unlocked
[Thu Jul 22 07:53:11.972515 2021] [wsgi:error] [pid 11102:tid 139959273891584] [remote 79.183.188.151:58906]   File "<frozen importlib._bootstrap_external>", line 728, in exec_module
[Thu Jul 22 07:53:11.972520 2021] [wsgi:error] [pid 11102:tid 139959273891584] [remote 79.183.188.151:58906]   File "<frozen importlib._bootstrap>", line 219, in _call_with_frames_removed
[Thu Jul 22 07:53:11.972526 2021] [wsgi:error] [pid 11102:tid 139959273891584] [remote 79.183.188.151:58906]   File "/mazebolt_project/django/mazebolt_project/mazebolt_project/settings.py", line 58, in <module>
[Thu Jul 22 07:53:11.972529 2021] [wsgi:error] [pid 11102:tid 139959273891584] [remote 79.183.188.151:58906]     'DIRS': [os.path.join(BASE_DIR, 'templates')],
[Thu Jul 22 07:53:11.972543 2021] [wsgi:error] [pid 11102:tid 139959273891584] [remote 79.183.188.151:58906] NameError: name 'os' is not defined
[Thu Jul 22 07:53:12.207177 2021] [wsgi:error] [pid 11102:tid 139959231887104] [remote 79.183.188.151:61506] mod_wsgi (pid=11102): Failed to exec Python script file '/mazebolt_project/django/mazebolt_project/mazebolt_project/wsgi.py'.
[Thu Jul 22 07:53:12.207233 2021] [wsgi:error] [pid 11102:tid 139959231887104] [remote 79.183.188.151:61506] mod_wsgi (pid=11102): Exception occurred processing WSGI script '/mazebolt_project/django/mazebolt_project/mazebolt_project/wsgi.py'.
[Thu Jul 22 07:53:12.207369 2021] [wsgi:error] [pid 11102:tid 139959231887104] [remote 79.183.188.151:61506] Traceback (most recent call last):
[Thu Jul 22 07:53:12.207413 2021] [wsgi:error] [pid 11102:tid 139959231887104] [remote 79.183.188.151:61506]   File "/mazebolt_project/django/mazebolt_project/mazebolt_project/wsgi.py", line 16, in <module>
[Thu Jul 22 07:53:12.207417 2021] [wsgi:error] [pid 11102:tid 139959231887104] [remote 79.183.188.151:61506]     application = get_wsgi_application()
[Thu Jul 22 07:53:12.207423 2021] [wsgi:error] [pid 11102:tid 139959231887104] [remote 79.183.188.151:61506]   File "/mazebolt_project/venv/lib/python3.7/site-packages/django/core/wsgi.py", line 12, in get_wsgi_application
[Thu Jul 22 07:53:12.207427 2021] [wsgi:error] [pid 11102:tid 139959231887104] [remote 79.183.188.151:61506]     django.setup(set_prefix=False)
[Thu Jul 22 07:53:12.207432 2021] [wsgi:error] [pid 11102:tid 139959231887104] [remote 79.183.188.151:61506]   File "/mazebolt_project/venv/lib/python3.7/site-packages/django/__init__.py", line 19, in setup
[Thu Jul 22 07:53:12.207436 2021] [wsgi:error] [pid 11102:tid 139959231887104] [remote 79.183.188.151:61506]     configure_logging(settings.LOGGING_CONFIG, settings.LOGGING)
[Thu Jul 22 07:53:12.207441 2021] [wsgi:error] [pid 11102:tid 139959231887104] [remote 79.183.188.151:61506]   File "/mazebolt_project/venv/lib/python3.7/site-packages/django/conf/__init__.py", line 82, in __getattr__
[Thu Jul 22 07:53:12.207444 2021] [wsgi:error] [pid 11102:tid 139959231887104] [remote 79.183.188.151:61506]     self._setup(name)
[Thu Jul 22 07:53:12.207449 2021] [wsgi:error] [pid 11102:tid 139959231887104] [remote 79.183.188.151:61506]   File "/mazebolt_project/venv/lib/python3.7/site-packages/django/conf/__init__.py", line 69, in _setup
[Thu Jul 22 07:53:12.207463 2021] [wsgi:error] [pid 11102:tid 139959231887104] [remote 79.183.188.151:61506]     self._wrapped = Settings(settings_module)
[Thu Jul 22 07:53:12.207468 2021] [wsgi:error] [pid 11102:tid 139959231887104] [remote 79.183.188.151:61506]   File "/mazebolt_project/venv/lib/python3.7/site-packages/django/conf/__init__.py", line 170, in __init__
[Thu Jul 22 07:53:12.207472 2021] [wsgi:error] [pid 11102:tid 139959231887104] [remote 79.183.188.151:61506]     mod = importlib.import_module(self.SETTINGS_MODULE)
[Thu Jul 22 07:53:12.207476 2021] [wsgi:error] [pid 11102:tid 139959231887104] [remote 79.183.188.151:61506]   File "/usr/lib/python3.7/importlib/__init__.py", line 127, in import_module
[Thu Jul 22 07:53:12.207480 2021] [wsgi:error] [pid 11102:tid 139959231887104] [remote 79.183.188.151:61506]     return _bootstrap._gcd_import(name[level:], package, level)
[Thu Jul 22 07:53:12.207485 2021] [wsgi:error] [pid 11102:tid 139959231887104] [remote 79.183.188.151:61506]   File "<frozen importlib._bootstrap>", line 1006, in _gcd_import
[Thu Jul 22 07:53:12.207490 2021] [wsgi:error] [pid 11102:tid 139959231887104] [remote 79.183.188.151:61506]   File "<frozen importlib._bootstrap>", line 983, in _find_and_load
[Thu Jul 22 07:53:12.207495 2021] [wsgi:error] [pid 11102:tid 139959231887104] [remote 79.183.188.151:61506]   File "<frozen importlib._bootstrap>", line 967, in _find_and_load_unlocked
[Thu Jul 22 07:53:12.207500 2021] [wsgi:error] [pid 11102:tid 139959231887104] [remote 79.183.188.151:61506]   File "<frozen importlib._bootstrap>", line 677, in _load_unlocked
[Thu Jul 22 07:53:12.207505 2021] [wsgi:error] [pid 11102:tid 139959231887104] [remote 79.183.188.151:61506]   File "<frozen importlib._bootstrap_external>", line 728, in exec_module
[Thu Jul 22 07:53:12.207509 2021] [wsgi:error] [pid 11102:tid 139959231887104] [remote 79.183.188.151:61506]   File "<frozen importlib._bootstrap>", line 219, in _call_with_frames_removed
[Thu Jul 22 07:53:12.207515 2021] [wsgi:error] [pid 11102:tid 139959231887104] [remote 79.183.188.151:61506]   File "/mazebolt_project/django/mazebolt_project/mazebolt_project/settings.py", line 58, in <module>
[Thu Jul 22 07:53:12.207518 2021] [wsgi:error] [pid 11102:tid 139959231887104] [remote 79.183.188.151:61506]     'DIRS': [os.path.join(BASE_DIR, 'templates')],
[Thu Jul 22 07:53:12.207531 2021] [wsgi:error] [pid 11102:tid 139959231887104] [remote 79.183.188.151:61506] NameError: name 'os' is not defined
[Thu Jul 22 07:53:12.400086 2021] [wsgi:error] [pid 11102:tid 139959273891584] [remote 79.183.188.151:54392] mod_wsgi (pid=11102): Failed to exec Python script file '/mazebolt_project/django/mazebolt_project/mazebolt_project/wsgi.py'.
[Thu Jul 22 07:53:12.400134 2021] [wsgi:error] [pid 11102:tid 139959273891584] [remote 79.183.188.151:54392] mod_wsgi (pid=11102): Exception occurred processing WSGI script '/mazebolt_project/django/mazebolt_project/mazebolt_project/wsgi.py'.
[Thu Jul 22 07:53:12.400330 2021] [wsgi:error] [pid 11102:tid 139959273891584] [remote 79.183.188.151:54392] Traceback (most recent call last):
[Thu Jul 22 07:53:12.400388 2021] [wsgi:error] [pid 11102:tid 139959273891584] [remote 79.183.188.151:54392]   File "/mazebolt_project/django/mazebolt_project/mazebolt_project/wsgi.py", line 16, in <module>
[Thu Jul 22 07:53:12.400393 2021] [wsgi:error] [pid 11102:tid 139959273891584] [remote 79.183.188.151:54392]     application = get_wsgi_application()
[Thu Jul 22 07:53:12.400399 2021] [wsgi:error] [pid 11102:tid 139959273891584] [remote 79.183.188.151:54392]   File "/mazebolt_project/venv/lib/python3.7/site-packages/django/core/wsgi.py", line 12, in get_wsgi_application
[Thu Jul 22 07:53:12.400403 2021] [wsgi:error] [pid 11102:tid 139959273891584] [remote 79.183.188.151:54392]     django.setup(set_prefix=False)
[Thu Jul 22 07:53:12.400408 2021] [wsgi:error] [pid 11102:tid 139959273891584] [remote 79.183.188.151:54392]   File "/mazebolt_project/venv/lib/python3.7/site-packages/django/__init__.py", line 19, in setup
[Thu Jul 22 07:53:12.400424 2021] [wsgi:error] [pid 11102:tid 139959273891584] [remote 79.183.188.151:54392]     configure_logging(settings.LOGGING_CONFIG, settings.LOGGING)
[Thu Jul 22 07:53:12.400429 2021] [wsgi:error] [pid 11102:tid 139959273891584] [remote 79.183.188.151:54392]   File "/mazebolt_project/venv/lib/python3.7/site-packages/django/conf/__init__.py", line 82, in __getattr__
[Thu Jul 22 07:53:12.400433 2021] [wsgi:error] [pid 11102:tid 139959273891584] [remote 79.183.188.151:54392]     self._setup(name)
[Thu Jul 22 07:53:12.400438 2021] [wsgi:error] [pid 11102:tid 139959273891584] [remote 79.183.188.151:54392]   File "/mazebolt_project/venv/lib/python3.7/site-packages/django/conf/__init__.py", line 69, in _setup
[Thu Jul 22 07:53:12.400442 2021] [wsgi:error] [pid 11102:tid 139959273891584] [remote 79.183.188.151:54392]     self._wrapped = Settings(settings_module)
[Thu Jul 22 07:53:12.400446 2021] [wsgi:error] [pid 11102:tid 139959273891584] [remote 79.183.188.151:54392]   File "/mazebolt_project/venv/lib/python3.7/site-packages/django/conf/__init__.py", line 170, in __init__
[Thu Jul 22 07:53:12.400450 2021] [wsgi:error] [pid 11102:tid 139959273891584] [remote 79.183.188.151:54392]     mod = importlib.import_module(self.SETTINGS_MODULE)
[Thu Jul 22 07:53:12.400455 2021] [wsgi:error] [pid 11102:tid 139959273891584] [remote 79.183.188.151:54392]   File "/usr/lib/python3.7/importlib/__init__.py", line 127, in import_module
[Thu Jul 22 07:53:12.400458 2021] [wsgi:error] [pid 11102:tid 139959273891584] [remote 79.183.188.151:54392]     return _bootstrap._gcd_import(name[level:], package, level)
[Thu Jul 22 07:53:12.400463 2021] [wsgi:error] [pid 11102:tid 139959273891584] [remote 79.183.188.151:54392]   File "<frozen importlib._bootstrap>", line 1006, in _gcd_import
[Thu Jul 22 07:53:12.400468 2021] [wsgi:error] [pid 11102:tid 139959273891584] [remote 79.183.188.151:54392]   File "<frozen importlib._bootstrap>", line 983, in _find_and_load
[Thu Jul 22 07:53:12.400473 2021] [wsgi:error] [pid 11102:tid 139959273891584] [remote 79.183.188.151:54392]   File "<frozen importlib._bootstrap>", line 967, in _find_and_load_unlocked
[Thu Jul 22 07:53:12.400478 2021] [wsgi:error] [pid 11102:tid 139959273891584] [remote 79.183.188.151:54392]   File "<frozen importlib._bootstrap>", line 677, in _load_unlocked
[Thu Jul 22 07:53:12.400483 2021] [wsgi:error] [pid 11102:tid 139959273891584] [remote 79.183.188.151:54392]   File "<frozen importlib._bootstrap_external>", line 728, in exec_module
[Thu Jul 22 07:53:12.400488 2021] [wsgi:error] [pid 11102:tid 139959273891584] [remote 79.183.188.151:54392]   File "<frozen importlib._bootstrap>", line 219, in _call_with_frames_removed
[Thu Jul 22 07:53:12.400494 2021] [wsgi:error] [pid 11102:tid 139959273891584] [remote 79.183.188.151:54392]   File "/mazebolt_project/django/mazebolt_project/mazebolt_project/settings.py", line 58, in <module>
[Thu Jul 22 07:53:12.400499 2021] [wsgi:error] [pid 11102:tid 139959273891584] [remote 79.183.188.151:54392]     'DIRS': [os.path.join(BASE_DIR, 'templates')],
[Thu Jul 22 07:53:12.400513 2021] [wsgi:error] [pid 11102:tid 139959273891584] [remote 79.183.188.151:54392] NameError: name 'os' is not defined
[Thu Jul 22 07:53:12.584504 2021] [wsgi:error] [pid 11102:tid 139959231887104] [remote 79.183.188.151:49905] mod_wsgi (pid=11102): Failed to exec Python script file '/mazebolt_project/django/mazebolt_project/mazebolt_project/wsgi.py'.
[Thu Jul 22 07:53:12.584553 2021] [wsgi:error] [pid 11102:tid 139959231887104] [remote 79.183.188.151:49905] mod_wsgi (pid=11102): Exception occurred processing WSGI script '/mazebolt_project/django/mazebolt_project/mazebolt_project/wsgi.py'.
[Thu Jul 22 07:53:12.584688 2021] [wsgi:error] [pid 11102:tid 139959231887104] [remote 79.183.188.151:49905] Traceback (most recent call last):
[Thu Jul 22 07:53:12.584734 2021] [wsgi:error] [pid 11102:tid 139959231887104] [remote 79.183.188.151:49905]   File "/mazebolt_project/django/mazebolt_project/mazebolt_project/wsgi.py", line 16, in <module>
[Thu Jul 22 07:53:12.584750 2021] [wsgi:error] [pid 11102:tid 139959231887104] [remote 79.183.188.151:49905]     application = get_wsgi_application()
[Thu Jul 22 07:53:12.584755 2021] [wsgi:error] [pid 11102:tid 139959231887104] [remote 79.183.188.151:49905]   File "/mazebolt_project/venv/lib/python3.7/site-packages/django/core/wsgi.py", line 12, in get_wsgi_application
[Thu Jul 22 07:53:12.584761 2021] [wsgi:error] [pid 11102:tid 139959231887104] [remote 79.183.188.151:49905]     django.setup(set_prefix=False)
[Thu Jul 22 07:53:12.584767 2021] [wsgi:error] [pid 11102:tid 139959231887104] [remote 79.183.188.151:49905]   File "/mazebolt_project/venv/lib/python3.7/site-packages/django/__init__.py", line 19, in setup
[Thu Jul 22 07:53:12.584771 2021] [wsgi:error] [pid 11102:tid 139959231887104] [remote 79.183.188.151:49905]     configure_logging(settings.LOGGING_CONFIG, settings.LOGGING)
[Thu Jul 22 07:53:12.584776 2021] [wsgi:error] [pid 11102:tid 139959231887104] [remote 79.183.188.151:49905]   File "/mazebolt_project/venv/lib/python3.7/site-packages/django/conf/__init__.py", line 82, in __getattr__
[Thu Jul 22 07:53:12.584780 2021] [wsgi:error] [pid 11102:tid 139959231887104] [remote 79.183.188.151:49905]     self._setup(name)
[Thu Jul 22 07:53:12.584784 2021] [wsgi:error] [pid 11102:tid 139959231887104] [remote 79.183.188.151:49905]   File "/mazebolt_project/venv/lib/python3.7/site-packages/django/conf/__init__.py", line 69, in _setup
[Thu Jul 22 07:53:12.584788 2021] [wsgi:error] [pid 11102:tid 139959231887104] [remote 79.183.188.151:49905]     self._wrapped = Settings(settings_module)
[Thu Jul 22 07:53:12.584793 2021] [wsgi:error] [pid 11102:tid 139959231887104] [remote 79.183.188.151:49905]   File "/mazebolt_project/venv/lib/python3.7/site-packages/django/conf/__init__.py", line 170, in __init__
[Thu Jul 22 07:53:12.584796 2021] [wsgi:error] [pid 11102:tid 139959231887104] [remote 79.183.188.151:49905]     mod = importlib.import_module(self.SETTINGS_MODULE)
[Thu Jul 22 07:53:12.584801 2021] [wsgi:error] [pid 11102:tid 139959231887104] [remote 79.183.188.151:49905]   File "/usr/lib/python3.7/importlib/__init__.py", line 127, in import_module
[Thu Jul 22 07:53:12.584805 2021] [wsgi:error] [pid 11102:tid 139959231887104] [remote 79.183.188.151:49905]     return _bootstrap._gcd_import(name[level:], package, level)
[Thu Jul 22 07:53:12.584809 2021] [wsgi:error] [pid 11102:tid 139959231887104] [remote 79.183.188.151:49905]   File "<frozen importlib._bootstrap>", line 1006, in _gcd_import
[Thu Jul 22 07:53:12.584814 2021] [wsgi:error] [pid 11102:tid 139959231887104] [remote 79.183.188.151:49905]   File "<frozen importlib._bootstrap>", line 983, in _find_and_load
[Thu Jul 22 07:53:12.584819 2021] [wsgi:error] [pid 11102:tid 139959231887104] [remote 79.183.188.151:49905]   File "<frozen importlib._bootstrap>", line 967, in _find_and_load_unlocked
[Thu Jul 22 07:53:12.584824 2021] [wsgi:error] [pid 11102:tid 139959231887104] [remote 79.183.188.151:49905]   File "<frozen importlib._bootstrap>", line 677, in _load_unlocked
[Thu Jul 22 07:53:12.584829 2021] [wsgi:error] [pid 11102:tid 139959231887104] [remote 79.183.188.151:49905]   File "<frozen importlib._bootstrap_external>", line 728, in exec_module
[Thu Jul 22 07:53:12.584834 2021] [wsgi:error] [pid 11102:tid 139959231887104] [remote 79.183.188.151:49905]   File "<frozen importlib._bootstrap>", line 219, in _call_with_frames_removed
[Thu Jul 22 07:53:12.584839 2021] [wsgi:error] [pid 11102:tid 139959231887104] [remote 79.183.188.151:49905]   File "/mazebolt_project/django/mazebolt_project/mazebolt_project/settings.py", line 58, in <module>
[Thu Jul 22 07:53:12.584843 2021] [wsgi:error] [pid 11102:tid 139959231887104] [remote 79.183.188.151:49905]     'DIRS': [os.path.join(BASE_DIR, 'templates')],
[Thu Jul 22 07:53:12.584855 2021] [wsgi:error] [pid 11102:tid 139959231887104] [remote 79.183.188.151:49905] NameError: name 'os' is not defined
[Thu Jul 22 07:53:12.754862 2021] [wsgi:error] [pid 11102:tid 139959273891584] [remote 79.183.188.151:62195] mod_wsgi (pid=11102): Failed to exec Python script file '/mazebolt_project/django/mazebolt_project/mazebolt_project/wsgi.py'.
[Thu Jul 22 07:53:12.754924 2021] [wsgi:error] [pid 11102:tid 139959273891584] [remote 79.183.188.151:62195] mod_wsgi (pid=11102): Exception occurred processing WSGI script '/mazebolt_project/django/mazebolt_project/mazebolt_project/wsgi.py'.
[Thu Jul 22 07:53:12.755062 2021] [wsgi:error] [pid 11102:tid 139959273891584] [remote 79.183.188.151:62195] Traceback (most recent call last):
[Thu Jul 22 07:53:12.755106 2021] [wsgi:error] [pid 11102:tid 139959273891584] [remote 79.183.188.151:62195]   File "/mazebolt_project/django/mazebolt_project/mazebolt_project/wsgi.py", line 16, in <module>
[Thu Jul 22 07:53:12.755111 2021] [wsgi:error] [pid 11102:tid 139959273891584] [remote 79.183.188.151:62195]     application = get_wsgi_application()
[Thu Jul 22 07:53:12.755117 2021] [wsgi:error] [pid 11102:tid 139959273891584] [remote 79.183.188.151:62195]   File "/mazebolt_project/venv/lib/python3.7/site-packages/django/core/wsgi.py", line 12, in get_wsgi_application
[Thu Jul 22 07:53:12.755120 2021] [wsgi:error] [pid 11102:tid 139959273891584] [remote 79.183.188.151:62195]     django.setup(set_prefix=False)
[Thu Jul 22 07:53:12.755126 2021] [wsgi:error] [pid 11102:tid 139959273891584] [remote 79.183.188.151:62195]   File "/mazebolt_project/venv/lib/python3.7/site-packages/django/__init__.py", line 19, in setup
[Thu Jul 22 07:53:12.755129 2021] [wsgi:error] [pid 11102:tid 139959273891584] [remote 79.183.188.151:62195]     configure_logging(settings.LOGGING_CONFIG, settings.LOGGING)
[Thu Jul 22 07:53:12.755134 2021] [wsgi:error] [pid 11102:tid 139959273891584] [remote 79.183.188.151:62195]   File "/mazebolt_project/venv/lib/python3.7/site-packages/django/conf/__init__.py", line 82, in __getattr__
[Thu Jul 22 07:53:12.755138 2021] [wsgi:error] [pid 11102:tid 139959273891584] [remote 79.183.188.151:62195]     self._setup(name)
[Thu Jul 22 07:53:12.755143 2021] [wsgi:error] [pid 11102:tid 139959273891584] [remote 79.183.188.151:62195]   File "/mazebolt_project/venv/lib/python3.7/site-packages/django/conf/__init__.py", line 69, in _setup
[Thu Jul 22 07:53:12.755147 2021] [wsgi:error] [pid 11102:tid 139959273891584] [remote 79.183.188.151:62195]     self._wrapped = Settings(settings_module)
[Thu Jul 22 07:53:12.755151 2021] [wsgi:error] [pid 11102:tid 139959273891584] [remote 79.183.188.151:62195]   File "/mazebolt_project/venv/lib/python3.7/site-packages/django/conf/__init__.py", line 170, in __init__
[Thu Jul 22 07:53:12.755155 2021] [wsgi:error] [pid 11102:tid 139959273891584] [remote 79.183.188.151:62195]     mod = importlib.import_module(self.SETTINGS_MODULE)
[Thu Jul 22 07:53:12.755160 2021] [wsgi:error] [pid 11102:tid 139959273891584] [remote 79.183.188.151:62195]   File "/usr/lib/python3.7/importlib/__init__.py", line 127, in import_module
[Thu Jul 22 07:53:12.755163 2021] [wsgi:error] [pid 11102:tid 139959273891584] [remote 79.183.188.151:62195]     return _bootstrap._gcd_import(name[level:], package, level)
[Thu Jul 22 07:53:12.755168 2021] [wsgi:error] [pid 11102:tid 139959273891584] [remote 79.183.188.151:62195]   File "<frozen importlib._bootstrap>", line 1006, in _gcd_import
[Thu Jul 22 07:53:12.755173 2021] [wsgi:error] [pid 11102:tid 139959273891584] [remote 79.183.188.151:62195]   File "<frozen importlib._bootstrap>", line 983, in _find_and_load
[Thu Jul 22 07:53:12.755178 2021] [wsgi:error] [pid 11102:tid 139959273891584] [remote 79.183.188.151:62195]   File "<frozen importlib._bootstrap>", line 967, in _find_and_load_unlocked
[Thu Jul 22 07:53:12.755183 2021] [wsgi:error] [pid 11102:tid 139959273891584] [remote 79.183.188.151:62195]   File "<frozen importlib._bootstrap>", line 677, in _load_unlocked
[Thu Jul 22 07:53:12.755188 2021] [wsgi:error] [pid 11102:tid 139959273891584] [remote 79.183.188.151:62195]   File "<frozen importlib._bootstrap_external>", line 728, in exec_module
[Thu Jul 22 07:53:12.755194 2021] [wsgi:error] [pid 11102:tid 139959273891584] [remote 79.183.188.151:62195]   File "<frozen importlib._bootstrap>", line 219, in _call_with_frames_removed
[Thu Jul 22 07:53:12.755204 2021] [wsgi:error] [pid 11102:tid 139959273891584] [remote 79.183.188.151:62195]   File "/mazebolt_project/django/mazebolt_project/mazebolt_project/settings.py", line 58, in <module>
[Thu Jul 22 07:53:12.755208 2021] [wsgi:error] [pid 11102:tid 139959273891584] [remote 79.183.188.151:62195]     'DIRS': [os.path.join(BASE_DIR, 'templates')],
[Thu Jul 22 07:53:12.755221 2021] [wsgi:error] [pid 11102:tid 139959273891584] [remote 79.183.188.151:62195] NameError: name 'os' is not defined
[Thu Jul 22 08:03:03.845919 2021] [wsgi:error] [pid 11201:tid 139628414748416] [remote 79.183.188.151:63544] Internal Server Error: /
[Thu Jul 22 08:03:03.845981 2021] [wsgi:error] [pid 11201:tid 139628414748416] [remote 79.183.188.151:63544] Traceback (most recent call last):
[Thu Jul 22 08:03:03.845986 2021] [wsgi:error] [pid 11201:tid 139628414748416] [remote 79.183.188.151:63544]   File "/mazebolt_project/venv/lib/python3.7/site-packages/django/core/handlers/exception.py", line 47, in inner
[Thu Jul 22 08:03:03.845991 2021] [wsgi:error] [pid 11201:tid 139628414748416] [remote 79.183.188.151:63544]     response = get_response(request)
[Thu Jul 22 08:03:03.845996 2021] [wsgi:error] [pid 11201:tid 139628414748416] [remote 79.183.188.151:63544]   File "/mazebolt_project/venv/lib/python3.7/site-packages/django/core/handlers/base.py", line 181, in _get_response
[Thu Jul 22 08:03:03.846000 2021] [wsgi:error] [pid 11201:tid 139628414748416] [remote 79.183.188.151:63544]     response = wrapped_callback(request, *callback_args, **callback_kwargs)
[Thu Jul 22 08:03:03.846004 2021] [wsgi:error] [pid 11201:tid 139628414748416] [remote 79.183.188.151:63544]   File "/mazebolt_project/django/mazebolt_project/mazebolt_project/views.py", line 10, in instance
[Thu Jul 22 08:03:03.846009 2021] [wsgi:error] [pid 11201:tid 139628414748416] [remote 79.183.188.151:63544]     return render(requset, 'instances.html', context)
[Thu Jul 22 08:03:03.846013 2021] [wsgi:error] [pid 11201:tid 139628414748416] [remote 79.183.188.151:63544]   File "/mazebolt_project/venv/lib/python3.7/site-packages/django/shortcuts.py", line 19, in render
[Thu Jul 22 08:03:03.846017 2021] [wsgi:error] [pid 11201:tid 139628414748416] [remote 79.183.188.151:63544]     content = loader.render_to_string(template_name, context, request, using=using)
[Thu Jul 22 08:03:03.846021 2021] [wsgi:error] [pid 11201:tid 139628414748416] [remote 79.183.188.151:63544]   File "/mazebolt_project/venv/lib/python3.7/site-packages/django/template/loader.py", line 61, in render_to_string
[Thu Jul 22 08:03:03.846025 2021] [wsgi:error] [pid 11201:tid 139628414748416] [remote 79.183.188.151:63544]     template = get_template(template_name, using=using)
[Thu Jul 22 08:03:03.846029 2021] [wsgi:error] [pid 11201:tid 139628414748416] [remote 79.183.188.151:63544]   File "/mazebolt_project/venv/lib/python3.7/site-packages/django/template/loader.py", line 19, in get_template
[Thu Jul 22 08:03:03.846034 2021] [wsgi:error] [pid 11201:tid 139628414748416] [remote 79.183.188.151:63544]     raise TemplateDoesNotExist(template_name, chain=chain)
[Thu Jul 22 08:03:03.846038 2021] [wsgi:error] [pid 11201:tid 139628414748416] [remote 79.183.188.151:63544] django.template.exceptions.TemplateDoesNotExist: instances.html
Exception ignored in: <function BaseEventLoop.__del__ at 0x7efdbe13da60>
Traceback (most recent call last):
  File "/usr/lib/python3.7/asyncio/base_events.py", line 622, in __del__
NameError: name 'ResourceWarning' is not defined
[Thu Jul 22 08:14:13.158044 2021] [wsgi:error] [pid 11300:tid 139814966384384] [remote 79.183.188.151:50408] Internal Server Error: /
[Thu Jul 22 08:14:13.158098 2021] [wsgi:error] [pid 11300:tid 139814966384384] [remote 79.183.188.151:50408] Traceback (most recent call last):
[Thu Jul 22 08:14:13.158103 2021] [wsgi:error] [pid 11300:tid 139814966384384] [remote 79.183.188.151:50408]   File "/mazebolt_project/venv/lib/python3.7/site-packages/django/core/handlers/exception.py", line 47, in inner
[Thu Jul 22 08:14:13.158144 2021] [wsgi:error] [pid 11300:tid 139814966384384] [remote 79.183.188.151:50408]     response = get_response(request)
[Thu Jul 22 08:14:13.158148 2021] [wsgi:error] [pid 11300:tid 139814966384384] [remote 79.183.188.151:50408]   File "/mazebolt_project/venv/lib/python3.7/site-packages/django/core/handlers/base.py", line 181, in _get_response
[Thu Jul 22 08:14:13.158152 2021] [wsgi:error] [pid 11300:tid 139814966384384] [remote 79.183.188.151:50408]     response = wrapped_callback(request, *callback_args, **callback_kwargs)
[Thu Jul 22 08:14:13.158155 2021] [wsgi:error] [pid 11300:tid 139814966384384] [remote 79.183.188.151:50408]   File "/mazebolt_project/django/mazebolt_project/mazebolt_project/views.py", line 10, in instance
[Thu Jul 22 08:14:13.158159 2021] [wsgi:error] [pid 11300:tid 139814966384384] [remote 79.183.188.151:50408]     return render(requset, 'instances.html', context)
[Thu Jul 22 08:14:13.158162 2021] [wsgi:error] [pid 11300:tid 139814966384384] [remote 79.183.188.151:50408]   File "/mazebolt_project/venv/lib/python3.7/site-packages/django/shortcuts.py", line 19, in render
[Thu Jul 22 08:14:13.158166 2021] [wsgi:error] [pid 11300:tid 139814966384384] [remote 79.183.188.151:50408]     content = loader.render_to_string(template_name, context, request, using=using)
[Thu Jul 22 08:14:13.158169 2021] [wsgi:error] [pid 11300:tid 139814966384384] [remote 79.183.188.151:50408]   File "/mazebolt_project/venv/lib/python3.7/site-packages/django/template/loader.py", line 61, in render_to_string
[Thu Jul 22 08:14:13.158172 2021] [wsgi:error] [pid 11300:tid 139814966384384] [remote 79.183.188.151:50408]     template = get_template(template_name, using=using)
[Thu Jul 22 08:14:13.158176 2021] [wsgi:error] [pid 11300:tid 139814966384384] [remote 79.183.188.151:50408]   File "/mazebolt_project/venv/lib/python3.7/site-packages/django/template/loader.py", line 15, in get_template
[Thu Jul 22 08:14:13.158179 2021] [wsgi:error] [pid 11300:tid 139814966384384] [remote 79.183.188.151:50408]     return engine.get_template(template_name)
[Thu Jul 22 08:14:13.158183 2021] [wsgi:error] [pid 11300:tid 139814966384384] [remote 79.183.188.151:50408]   File "/mazebolt_project/venv/lib/python3.7/site-packages/django/template/backends/django.py", line 34, in get_template
[Thu Jul 22 08:14:13.158186 2021] [wsgi:error] [pid 11300:tid 139814966384384] [remote 79.183.188.151:50408]     return Template(self.engine.get_template(template_name), self)
[Thu Jul 22 08:14:13.158190 2021] [wsgi:error] [pid 11300:tid 139814966384384] [remote 79.183.188.151:50408]   File "/mazebolt_project/venv/lib/python3.7/site-packages/django/template/engine.py", line 143, in get_template
[Thu Jul 22 08:14:13.158193 2021] [wsgi:error] [pid 11300:tid 139814966384384] [remote 79.183.188.151:50408]     template, origin = self.find_template(template_name)
[Thu Jul 22 08:14:13.158196 2021] [wsgi:error] [pid 11300:tid 139814966384384] [remote 79.183.188.151:50408]   File "/mazebolt_project/venv/lib/python3.7/site-packages/django/template/engine.py", line 125, in find_template
[Thu Jul 22 08:14:13.158200 2021] [wsgi:error] [pid 11300:tid 139814966384384] [remote 79.183.188.151:50408]     template = loader.get_template(name, skip=skip)
[Thu Jul 22 08:14:13.158203 2021] [wsgi:error] [pid 11300:tid 139814966384384] [remote 79.183.188.151:50408]   File "/mazebolt_project/venv/lib/python3.7/site-packages/django/template/loaders/base.py", line 30, in get_template
[Thu Jul 22 08:14:13.158206 2021] [wsgi:error] [pid 11300:tid 139814966384384] [remote 79.183.188.151:50408]     contents, origin, origin.template_name, self.engine,
[Thu Jul 22 08:14:13.158210 2021] [wsgi:error] [pid 11300:tid 139814966384384] [remote 79.183.188.151:50408]   File "/mazebolt_project/venv/lib/python3.7/site-packages/django/template/base.py", line 155, in __init__
[Thu Jul 22 08:14:13.158213 2021] [wsgi:error] [pid 11300:tid 139814966384384] [remote 79.183.188.151:50408]     self.nodelist = self.compile_nodelist()
[Thu Jul 22 08:14:13.158216 2021] [wsgi:error] [pid 11300:tid 139814966384384] [remote 79.183.188.151:50408]   File "/mazebolt_project/venv/lib/python3.7/site-packages/django/template/base.py", line 193, in compile_nodelist
[Thu Jul 22 08:14:13.158233 2021] [wsgi:error] [pid 11300:tid 139814966384384] [remote 79.183.188.151:50408]     return parser.parse()
[Thu Jul 22 08:14:13.158236 2021] [wsgi:error] [pid 11300:tid 139814966384384] [remote 79.183.188.151:50408]   File "/mazebolt_project/venv/lib/python3.7/site-packages/django/template/base.py", line 478, in parse
[Thu Jul 22 08:14:13.158239 2021] [wsgi:error] [pid 11300:tid 139814966384384] [remote 79.183.188.151:50408]     raise self.error(token, e)
[Thu Jul 22 08:14:13.158242 2021] [wsgi:error] [pid 11300:tid 139814966384384] [remote 79.183.188.151:50408]   File "/mazebolt_project/venv/lib/python3.7/site-packages/django/template/base.py", line 476, in parse
[Thu Jul 22 08:14:13.158246 2021] [wsgi:error] [pid 11300:tid 139814966384384] [remote 79.183.188.151:50408]     compiled_result = compile_func(self, token)
[Thu Jul 22 08:14:13.158249 2021] [wsgi:error] [pid 11300:tid 139814966384384] [remote 79.183.188.151:50408]   File "/mazebolt_project/venv/lib/python3.7/site-packages/django/template/loader_tags.py", line 278, in do_extends
[Thu Jul 22 08:14:13.158253 2021] [wsgi:error] [pid 11300:tid 139814966384384] [remote 79.183.188.151:50408]     nodelist = parser.parse()
[Thu Jul 22 08:14:13.158256 2021] [wsgi:error] [pid 11300:tid 139814966384384] [remote 79.183.188.151:50408]   File "/mazebolt_project/venv/lib/python3.7/site-packages/django/template/base.py", line 478, in parse
[Thu Jul 22 08:14:13.158259 2021] [wsgi:error] [pid 11300:tid 139814966384384] [remote 79.183.188.151:50408]     raise self.error(token, e)
[Thu Jul 22 08:14:13.158262 2021] [wsgi:error] [pid 11300:tid 139814966384384] [remote 79.183.188.151:50408]   File "/mazebolt_project/venv/lib/python3.7/site-packages/django/template/base.py", line 476, in parse
[Thu Jul 22 08:14:13.158266 2021] [wsgi:error] [pid 11300:tid 139814966384384] [remote 79.183.188.151:50408]     compiled_result = compile_func(self, token)
[Thu Jul 22 08:14:13.158269 2021] [wsgi:error] [pid 11300:tid 139814966384384] [remote 79.183.188.151:50408]   File "/mazebolt_project/venv/lib/python3.7/site-packages/django/template/loader_tags.py", line 216, in do_block
[Thu Jul 22 08:14:13.158272 2021] [wsgi:error] [pid 11300:tid 139814966384384] [remote 79.183.188.151:50408]     nodelist = parser.parse(('endblock',))
[Thu Jul 22 08:14:13.158275 2021] [wsgi:error] [pid 11300:tid 139814966384384] [remote 79.183.188.151:50408]   File "/mazebolt_project/venv/lib/python3.7/site-packages/django/template/base.py", line 478, in parse
[Thu Jul 22 08:14:13.158279 2021] [wsgi:error] [pid 11300:tid 139814966384384] [remote 79.183.188.151:50408]     raise self.error(token, e)
[Thu Jul 22 08:14:13.158282 2021] [wsgi:error] [pid 11300:tid 139814966384384] [remote 79.183.188.151:50408]   File "/mazebolt_project/venv/lib/python3.7/site-packages/django/template/base.py", line 476, in parse
[Thu Jul 22 08:14:13.158285 2021] [wsgi:error] [pid 11300:tid 139814966384384] [remote 79.183.188.151:50408]     compiled_result = compile_func(self, token)
[Thu Jul 22 08:14:13.158288 2021] [wsgi:error] [pid 11300:tid 139814966384384] [remote 79.183.188.151:50408]   File "/mazebolt_project/venv/lib/python3.7/site-packages/django/template/defaulttags.py", line 814, in do_for
[Thu Jul 22 08:14:13.158292 2021] [wsgi:error] [pid 11300:tid 139814966384384] [remote 79.183.188.151:50408]     nodelist_loop = parser.parse(('empty', 'endfor',))
[Thu Jul 22 08:14:13.158295 2021] [wsgi:error] [pid 11300:tid 139814966384384] [remote 79.183.188.151:50408]   File "/mazebolt_project/venv/lib/python3.7/site-packages/django/template/base.py", line 445, in parse
[Thu Jul 22 08:14:13.158298 2021] [wsgi:error] [pid 11300:tid 139814966384384] [remote 79.183.188.151:50408]     raise self.error(token, 'Empty variable tag on line %d' % token.lineno)
[Thu Jul 22 08:14:13.158302 2021] [wsgi:error] [pid 11300:tid 139814966384384] [remote 79.183.188.151:50408] django.template.exceptions.TemplateSyntaxError: Empty variable tag on line 17
[Thu Jul 22 08:20:04.490986 2021] [wsgi:error] [pid 11300:tid 139814865581824] [remote 74.82.47.4:33796] Internal Server Error: /
[Thu Jul 22 08:20:04.491110 2021] [wsgi:error] [pid 11300:tid 139814865581824] [remote 74.82.47.4:33796] Traceback (most recent call last):
[Thu Jul 22 08:20:04.491115 2021] [wsgi:error] [pid 11300:tid 139814865581824] [remote 74.82.47.4:33796]   File "/mazebolt_project/venv/lib/python3.7/site-packages/django/core/handlers/exception.py", line 47, in inner
[Thu Jul 22 08:20:04.491120 2021] [wsgi:error] [pid 11300:tid 139814865581824] [remote 74.82.47.4:33796]     response = get_response(request)
[Thu Jul 22 08:20:04.491123 2021] [wsgi:error] [pid 11300:tid 139814865581824] [remote 74.82.47.4:33796]   File "/mazebolt_project/venv/lib/python3.7/site-packages/django/core/handlers/base.py", line 181, in _get_response
[Thu Jul 22 08:20:04.491128 2021] [wsgi:error] [pid 11300:tid 139814865581824] [remote 74.82.47.4:33796]     response = wrapped_callback(request, *callback_args, **callback_kwargs)
[Thu Jul 22 08:20:04.491132 2021] [wsgi:error] [pid 11300:tid 139814865581824] [remote 74.82.47.4:33796]   File "/mazebolt_project/django/mazebolt_project/mazebolt_project/views.py", line 10, in instance
[Thu Jul 22 08:20:04.491136 2021] [wsgi:error] [pid 11300:tid 139814865581824] [remote 74.82.47.4:33796]     return render(requset, 'instances.html', context)
[Thu Jul 22 08:20:04.491139 2021] [wsgi:error] [pid 11300:tid 139814865581824] [remote 74.82.47.4:33796]   File "/mazebolt_project/venv/lib/python3.7/site-packages/django/shortcuts.py", line 19, in render
[Thu Jul 22 08:20:04.491143 2021] [wsgi:error] [pid 11300:tid 139814865581824] [remote 74.82.47.4:33796]     content = loader.render_to_string(template_name, context, request, using=using)
[Thu Jul 22 08:20:04.491147 2021] [wsgi:error] [pid 11300:tid 139814865581824] [remote 74.82.47.4:33796]   File "/mazebolt_project/venv/lib/python3.7/site-packages/django/template/loader.py", line 61, in render_to_string
[Thu Jul 22 08:20:04.491151 2021] [wsgi:error] [pid 11300:tid 139814865581824] [remote 74.82.47.4:33796]     template = get_template(template_name, using=using)
[Thu Jul 22 08:20:04.491154 2021] [wsgi:error] [pid 11300:tid 139814865581824] [remote 74.82.47.4:33796]   File "/mazebolt_project/venv/lib/python3.7/site-packages/django/template/loader.py", line 15, in get_template
[Thu Jul 22 08:20:04.491158 2021] [wsgi:error] [pid 11300:tid 139814865581824] [remote 74.82.47.4:33796]     return engine.get_template(template_name)
[Thu Jul 22 08:20:04.491162 2021] [wsgi:error] [pid 11300:tid 139814865581824] [remote 74.82.47.4:33796]   File "/mazebolt_project/venv/lib/python3.7/site-packages/django/template/backends/django.py", line 34, in get_template
[Thu Jul 22 08:20:04.491166 2021] [wsgi:error] [pid 11300:tid 139814865581824] [remote 74.82.47.4:33796]     return Template(self.engine.get_template(template_name), self)
[Thu Jul 22 08:20:04.491169 2021] [wsgi:error] [pid 11300:tid 139814865581824] [remote 74.82.47.4:33796]   File "/mazebolt_project/venv/lib/python3.7/site-packages/django/template/engine.py", line 143, in get_template
[Thu Jul 22 08:20:04.491173 2021] [wsgi:error] [pid 11300:tid 139814865581824] [remote 74.82.47.4:33796]     template, origin = self.find_template(template_name)
[Thu Jul 22 08:20:04.491177 2021] [wsgi:error] [pid 11300:tid 139814865581824] [remote 74.82.47.4:33796]   File "/mazebolt_project/venv/lib/python3.7/site-packages/django/template/engine.py", line 125, in find_template
[Thu Jul 22 08:20:04.491181 2021] [wsgi:error] [pid 11300:tid 139814865581824] [remote 74.82.47.4:33796]     template = loader.get_template(name, skip=skip)
[Thu Jul 22 08:20:04.491184 2021] [wsgi:error] [pid 11300:tid 139814865581824] [remote 74.82.47.4:33796]   File "/mazebolt_project/venv/lib/python3.7/site-packages/django/template/loaders/base.py", line 30, in get_template
[Thu Jul 22 08:20:04.491188 2021] [wsgi:error] [pid 11300:tid 139814865581824] [remote 74.82.47.4:33796]     contents, origin, origin.template_name, self.engine,
[Thu Jul 22 08:20:04.491214 2021] [wsgi:error] [pid 11300:tid 139814865581824] [remote 74.82.47.4:33796]   File "/mazebolt_project/venv/lib/python3.7/site-packages/django/template/base.py", line 155, in __init__
[Thu Jul 22 08:20:04.491218 2021] [wsgi:error] [pid 11300:tid 139814865581824] [remote 74.82.47.4:33796]     self.nodelist = self.compile_nodelist()
[Thu Jul 22 08:20:04.491221 2021] [wsgi:error] [pid 11300:tid 139814865581824] [remote 74.82.47.4:33796]   File "/mazebolt_project/venv/lib/python3.7/site-packages/django/template/base.py", line 193, in compile_nodelist
[Thu Jul 22 08:20:04.491224 2021] [wsgi:error] [pid 11300:tid 139814865581824] [remote 74.82.47.4:33796]     return parser.parse()
[Thu Jul 22 08:20:04.491227 2021] [wsgi:error] [pid 11300:tid 139814865581824] [remote 74.82.47.4:33796]   File "/mazebolt_project/venv/lib/python3.7/site-packages/django/template/base.py", line 478, in parse
[Thu Jul 22 08:20:04.491230 2021] [wsgi:error] [pid 11300:tid 139814865581824] [remote 74.82.47.4:33796]     raise self.error(token, e)
[Thu Jul 22 08:20:04.491234 2021] [wsgi:error] [pid 11300:tid 139814865581824] [remote 74.82.47.4:33796]   File "/mazebolt_project/venv/lib/python3.7/site-packages/django/template/base.py", line 476, in parse
[Thu Jul 22 08:20:04.491237 2021] [wsgi:error] [pid 11300:tid 139814865581824] [remote 74.82.47.4:33796]     compiled_result = compile_func(self, token)
[Thu Jul 22 08:20:04.491240 2021] [wsgi:error] [pid 11300:tid 139814865581824] [remote 74.82.47.4:33796]   File "/mazebolt_project/venv/lib/python3.7/site-packages/django/template/loader_tags.py", line 278, in do_extends
[Thu Jul 22 08:20:04.491243 2021] [wsgi:error] [pid 11300:tid 139814865581824] [remote 74.82.47.4:33796]     nodelist = parser.parse()
[Thu Jul 22 08:20:04.491246 2021] [wsgi:error] [pid 11300:tid 139814865581824] [remote 74.82.47.4:33796]   File "/mazebolt_project/venv/lib/python3.7/site-packages/django/template/base.py", line 478, in parse
[Thu Jul 22 08:20:04.491250 2021] [wsgi:error] [pid 11300:tid 139814865581824] [remote 74.82.47.4:33796]     raise self.error(token, e)
[Thu Jul 22 08:20:04.491253 2021] [wsgi:error] [pid 11300:tid 139814865581824] [remote 74.82.47.4:33796]   File "/mazebolt_project/venv/lib/python3.7/site-packages/django/template/base.py", line 476, in parse
[Thu Jul 22 08:20:04.491256 2021] [wsgi:error] [pid 11300:tid 139814865581824] [remote 74.82.47.4:33796]     compiled_result = compile_func(self, token)
[Thu Jul 22 08:20:04.491259 2021] [wsgi:error] [pid 11300:tid 139814865581824] [remote 74.82.47.4:33796]   File "/mazebolt_project/venv/lib/python3.7/site-packages/django/template/loader_tags.py", line 216, in do_block
[Thu Jul 22 08:20:04.491262 2021] [wsgi:error] [pid 11300:tid 139814865581824] [remote 74.82.47.4:33796]     nodelist = parser.parse(('endblock',))
[Thu Jul 22 08:20:04.491266 2021] [wsgi:error] [pid 11300:tid 139814865581824] [remote 74.82.47.4:33796]   File "/mazebolt_project/venv/lib/python3.7/site-packages/django/template/base.py", line 478, in parse
[Thu Jul 22 08:20:04.491269 2021] [wsgi:error] [pid 11300:tid 139814865581824] [remote 74.82.47.4:33796]     raise self.error(token, e)
[Thu Jul 22 08:20:04.491272 2021] [wsgi:error] [pid 11300:tid 139814865581824] [remote 74.82.47.4:33796]   File "/mazebolt_project/venv/lib/python3.7/site-packages/django/template/base.py", line 476, in parse
[Thu Jul 22 08:20:04.491275 2021] [wsgi:error] [pid 11300:tid 139814865581824] [remote 74.82.47.4:33796]     compiled_result = compile_func(self, token)
[Thu Jul 22 08:20:04.491278 2021] [wsgi:error] [pid 11300:tid 139814865581824] [remote 74.82.47.4:33796]   File "/mazebolt_project/venv/lib/python3.7/site-packages/django/template/defaulttags.py", line 814, in do_for
[Thu Jul 22 08:20:04.491282 2021] [wsgi:error] [pid 11300:tid 139814865581824] [remote 74.82.47.4:33796]     nodelist_loop = parser.parse(('empty', 'endfor',))
[Thu Jul 22 08:20:04.491285 2021] [wsgi:error] [pid 11300:tid 139814865581824] [remote 74.82.47.4:33796]   File "/mazebolt_project/venv/lib/python3.7/site-packages/django/template/base.py", line 445, in parse
[Thu Jul 22 08:20:04.491292 2021] [wsgi:error] [pid 11300:tid 139814865581824] [remote 74.82.47.4:33796]     raise self.error(token, 'Empty variable tag on line %d' % token.lineno)
[Thu Jul 22 08:20:04.491295 2021] [wsgi:error] [pid 11300:tid 139814865581824] [remote 74.82.47.4:33796] django.template.exceptions.TemplateSyntaxError: Empty variable tag on line 17
[Thu Jul 22 08:20:24.403343 2021] [wsgi:error] [pid 11300:tid 139814966384384] [remote 147.182.179.242:55370] Not Found: /boaform/admin/formLogin
Exception ignored in: <function BaseEventLoop.__del__ at 0x7f292debfa60>
Traceback (most recent call last):
  File "/usr/lib/python3.7/asyncio/base_events.py", line 622, in __del__
NameError: name 'ResourceWarning' is not defined
[Thu Jul 22 08:27:28.842877 2021] [wsgi:error] [pid 11399:tid 140718738609920] [remote 79.183.188.151:54642] Internal Server Error: /
[Thu Jul 22 08:27:28.842951 2021] [wsgi:error] [pid 11399:tid 140718738609920] [remote 79.183.188.151:54642] Traceback (most recent call last):
[Thu Jul 22 08:27:28.842956 2021] [wsgi:error] [pid 11399:tid 140718738609920] [remote 79.183.188.151:54642]   File "/mazebolt_project/venv/lib/python3.7/site-packages/django/core/handlers/exception.py", line 47, in inner
[Thu Jul 22 08:27:28.842961 2021] [wsgi:error] [pid 11399:tid 140718738609920] [remote 79.183.188.151:54642]     response = get_response(request)
[Thu Jul 22 08:27:28.842964 2021] [wsgi:error] [pid 11399:tid 140718738609920] [remote 79.183.188.151:54642]   File "/mazebolt_project/venv/lib/python3.7/site-packages/django/core/handlers/base.py", line 181, in _get_response
[Thu Jul 22 08:27:28.842969 2021] [wsgi:error] [pid 11399:tid 140718738609920] [remote 79.183.188.151:54642]     response = wrapped_callback(request, *callback_args, **callback_kwargs)
[Thu Jul 22 08:27:28.842973 2021] [wsgi:error] [pid 11399:tid 140718738609920] [remote 79.183.188.151:54642]   File "/mazebolt_project/django/mazebolt_project/mazebolt_project/views.py", line 10, in instance
[Thu Jul 22 08:27:28.842976 2021] [wsgi:error] [pid 11399:tid 140718738609920] [remote 79.183.188.151:54642]     return render(requset, 'instances.html', context)
[Thu Jul 22 08:27:28.842980 2021] [wsgi:error] [pid 11399:tid 140718738609920] [remote 79.183.188.151:54642]   File "/mazebolt_project/venv/lib/python3.7/site-packages/django/shortcuts.py", line 19, in render
[Thu Jul 22 08:27:28.842984 2021] [wsgi:error] [pid 11399:tid 140718738609920] [remote 79.183.188.151:54642]     content = loader.render_to_string(template_name, context, request, using=using)
[Thu Jul 22 08:27:28.842987 2021] [wsgi:error] [pid 11399:tid 140718738609920] [remote 79.183.188.151:54642]   File "/mazebolt_project/venv/lib/python3.7/site-packages/django/template/loader.py", line 61, in render_to_string
[Thu Jul 22 08:27:28.842991 2021] [wsgi:error] [pid 11399:tid 140718738609920] [remote 79.183.188.151:54642]     template = get_template(template_name, using=using)
[Thu Jul 22 08:27:28.842995 2021] [wsgi:error] [pid 11399:tid 140718738609920] [remote 79.183.188.151:54642]   File "/mazebolt_project/venv/lib/python3.7/site-packages/django/template/loader.py", line 15, in get_template
[Thu Jul 22 08:27:28.842999 2021] [wsgi:error] [pid 11399:tid 140718738609920] [remote 79.183.188.151:54642]     return engine.get_template(template_name)
[Thu Jul 22 08:27:28.843003 2021] [wsgi:error] [pid 11399:tid 140718738609920] [remote 79.183.188.151:54642]   File "/mazebolt_project/venv/lib/python3.7/site-packages/django/template/backends/django.py", line 34, in get_template
[Thu Jul 22 08:27:28.843007 2021] [wsgi:error] [pid 11399:tid 140718738609920] [remote 79.183.188.151:54642]     return Template(self.engine.get_template(template_name), self)
[Thu Jul 22 08:27:28.843010 2021] [wsgi:error] [pid 11399:tid 140718738609920] [remote 79.183.188.151:54642]   File "/mazebolt_project/venv/lib/python3.7/site-packages/django/template/engine.py", line 143, in get_template
[Thu Jul 22 08:27:28.843065 2021] [wsgi:error] [pid 11399:tid 140718738609920] [remote 79.183.188.151:54642]     template, origin = self.find_template(template_name)
[Thu Jul 22 08:27:28.843069 2021] [wsgi:error] [pid 11399:tid 140718738609920] [remote 79.183.188.151:54642]   File "/mazebolt_project/venv/lib/python3.7/site-packages/django/template/engine.py", line 125, in find_template
[Thu Jul 22 08:27:28.843072 2021] [wsgi:error] [pid 11399:tid 140718738609920] [remote 79.183.188.151:54642]     template = loader.get_template(name, skip=skip)
[Thu Jul 22 08:27:28.843076 2021] [wsgi:error] [pid 11399:tid 140718738609920] [remote 79.183.188.151:54642]   File "/mazebolt_project/venv/lib/python3.7/site-packages/django/template/loaders/base.py", line 30, in get_template
[Thu Jul 22 08:27:28.843079 2021] [wsgi:error] [pid 11399:tid 140718738609920] [remote 79.183.188.151:54642]     contents, origin, origin.template_name, self.engine,
[Thu Jul 22 08:27:28.843082 2021] [wsgi:error] [pid 11399:tid 140718738609920] [remote 79.183.188.151:54642]   File "/mazebolt_project/venv/lib/python3.7/site-packages/django/template/base.py", line 155, in __init__
[Thu Jul 22 08:27:28.843085 2021] [wsgi:error] [pid 11399:tid 140718738609920] [remote 79.183.188.151:54642]     self.nodelist = self.compile_nodelist()
[Thu Jul 22 08:27:28.843089 2021] [wsgi:error] [pid 11399:tid 140718738609920] [remote 79.183.188.151:54642]   File "/mazebolt_project/venv/lib/python3.7/site-packages/django/template/base.py", line 193, in compile_nodelist
[Thu Jul 22 08:27:28.843092 2021] [wsgi:error] [pid 11399:tid 140718738609920] [remote 79.183.188.151:54642]     return parser.parse()
[Thu Jul 22 08:27:28.843095 2021] [wsgi:error] [pid 11399:tid 140718738609920] [remote 79.183.188.151:54642]   File "/mazebolt_project/venv/lib/python3.7/site-packages/django/template/base.py", line 478, in parse
[Thu Jul 22 08:27:28.843098 2021] [wsgi:error] [pid 11399:tid 140718738609920] [remote 79.183.188.151:54642]     raise self.error(token, e)
[Thu Jul 22 08:27:28.843102 2021] [wsgi:error] [pid 11399:tid 140718738609920] [remote 79.183.188.151:54642]   File "/mazebolt_project/venv/lib/python3.7/site-packages/django/template/base.py", line 476, in parse
[Thu Jul 22 08:27:28.843105 2021] [wsgi:error] [pid 11399:tid 140718738609920] [remote 79.183.188.151:54642]     compiled_result = compile_func(self, token)
[Thu Jul 22 08:27:28.843108 2021] [wsgi:error] [pid 11399:tid 140718738609920] [remote 79.183.188.151:54642]   File "/mazebolt_project/venv/lib/python3.7/site-packages/django/template/loader_tags.py", line 278, in do_extends
[Thu Jul 22 08:27:28.843111 2021] [wsgi:error] [pid 11399:tid 140718738609920] [remote 79.183.188.151:54642]     nodelist = parser.parse()
[Thu Jul 22 08:27:28.843114 2021] [wsgi:error] [pid 11399:tid 140718738609920] [remote 79.183.188.151:54642]   File "/mazebolt_project/venv/lib/python3.7/site-packages/django/template/base.py", line 478, in parse
[Thu Jul 22 08:27:28.843118 2021] [wsgi:error] [pid 11399:tid 140718738609920] [remote 79.183.188.151:54642]     raise self.error(token, e)
[Thu Jul 22 08:27:28.843121 2021] [wsgi:error] [pid 11399:tid 140718738609920] [remote 79.183.188.151:54642]   File "/mazebolt_project/venv/lib/python3.7/site-packages/django/template/base.py", line 476, in parse
[Thu Jul 22 08:27:28.843124 2021] [wsgi:error] [pid 11399:tid 140718738609920] [remote 79.183.188.151:54642]     compiled_result = compile_func(self, token)
[Thu Jul 22 08:27:28.843127 2021] [wsgi:error] [pid 11399:tid 140718738609920] [remote 79.183.188.151:54642]   File "/mazebolt_project/venv/lib/python3.7/site-packages/django/template/loader_tags.py", line 216, in do_block
[Thu Jul 22 08:27:28.843131 2021] [wsgi:error] [pid 11399:tid 140718738609920] [remote 79.183.188.151:54642]     nodelist = parser.parse(('endblock',))
[Thu Jul 22 08:27:28.843134 2021] [wsgi:error] [pid 11399:tid 140718738609920] [remote 79.183.188.151:54642]   File "/mazebolt_project/venv/lib/python3.7/site-packages/django/template/base.py", line 483, in parse
[Thu Jul 22 08:27:28.843137 2021] [wsgi:error] [pid 11399:tid 140718738609920] [remote 79.183.188.151:54642]     self.unclosed_block_tag(parse_until)
[Thu Jul 22 08:27:28.843167 2021] [wsgi:error] [pid 11399:tid 140718738609920] [remote 79.183.188.151:54642]   File "/mazebolt_project/venv/lib/python3.7/site-packages/django/template/base.py", line 544, in unclosed_block_tag
[Thu Jul 22 08:27:28.843170 2021] [wsgi:error] [pid 11399:tid 140718738609920] [remote 79.183.188.151:54642]     raise self.error(token, msg)
[Thu Jul 22 08:27:28.843174 2021] [wsgi:error] [pid 11399:tid 140718738609920] [remote 79.183.188.151:54642] django.template.exceptions.TemplateSyntaxError: Unclosed tag on line 2: 'block'. Looking for one of: endblock.
Exception ignored in: <function BaseEventLoop.__del__ at 0x7ffb9bf33a60>
Traceback (most recent call last):
  File "/usr/lib/python3.7/asyncio/base_events.py", line 622, in __del__
NameError: name 'ResourceWarning' is not defined
[Thu Jul 22 08:33:52.856674 2021] [wsgi:error] [pid 11494:tid 140320361740032] [remote 79.183.188.151:52161] Internal Server Error: /create_test/
[Thu Jul 22 08:33:52.856733 2021] [wsgi:error] [pid 11494:tid 140320361740032] [remote 79.183.188.151:52161] Traceback (most recent call last):
[Thu Jul 22 08:33:52.856738 2021] [wsgi:error] [pid 11494:tid 140320361740032] [remote 79.183.188.151:52161]   File "/mazebolt_project/venv/lib/python3.7/site-packages/django/template/base.py", line 470, in parse
[Thu Jul 22 08:33:52.856742 2021] [wsgi:error] [pid 11494:tid 140320361740032] [remote 79.183.188.151:52161]     compile_func = self.tags[command]
[Thu Jul 22 08:33:52.856746 2021] [wsgi:error] [pid 11494:tid 140320361740032] [remote 79.183.188.151:52161] KeyError: 'endblock'
[Thu Jul 22 08:33:52.856749 2021] [wsgi:error] [pid 11494:tid 140320361740032] [remote 79.183.188.151:52161] 
[Thu Jul 22 08:33:52.856753 2021] [wsgi:error] [pid 11494:tid 140320361740032] [remote 79.183.188.151:52161] During handling of the above exception, another exception occurred:
[Thu Jul 22 08:33:52.856757 2021] [wsgi:error] [pid 11494:tid 140320361740032] [remote 79.183.188.151:52161] 
[Thu Jul 22 08:33:52.856760 2021] [wsgi:error] [pid 11494:tid 140320361740032] [remote 79.183.188.151:52161] Traceback (most recent call last):
[Thu Jul 22 08:33:52.856764 2021] [wsgi:error] [pid 11494:tid 140320361740032] [remote 79.183.188.151:52161]   File "/mazebolt_project/venv/lib/python3.7/site-packages/django/core/handlers/exception.py", line 47, in inner
[Thu Jul 22 08:33:52.856768 2021] [wsgi:error] [pid 11494:tid 140320361740032] [remote 79.183.188.151:52161]     response = get_response(request)
[Thu Jul 22 08:33:52.856771 2021] [wsgi:error] [pid 11494:tid 140320361740032] [remote 79.183.188.151:52161]   File "/mazebolt_project/venv/lib/python3.7/site-packages/django/core/handlers/base.py", line 181, in _get_response
[Thu Jul 22 08:33:52.856775 2021] [wsgi:error] [pid 11494:tid 140320361740032] [remote 79.183.188.151:52161]     response = wrapped_callback(request, *callback_args, **callback_kwargs)
[Thu Jul 22 08:33:52.856779 2021] [wsgi:error] [pid 11494:tid 140320361740032] [remote 79.183.188.151:52161]   File "/mazebolt_project/django/mazebolt_project/mazebolt_project/views.py", line 22, in create_test
[Thu Jul 22 08:33:52.856782 2021] [wsgi:error] [pid 11494:tid 140320361740032] [remote 79.183.188.151:52161]     return render(requset, 'create_test.html', selected_instances)
[Thu Jul 22 08:33:52.856786 2021] [wsgi:error] [pid 11494:tid 140320361740032] [remote 79.183.188.151:52161]   File "/mazebolt_project/venv/lib/python3.7/site-packages/django/shortcuts.py", line 19, in render
[Thu Jul 22 08:33:52.856790 2021] [wsgi:error] [pid 11494:tid 140320361740032] [remote 79.183.188.151:52161]     content = loader.render_to_string(template_name, context, request, using=using)
[Thu Jul 22 08:33:52.856793 2021] [wsgi:error] [pid 11494:tid 140320361740032] [remote 79.183.188.151:52161]   File "/mazebolt_project/venv/lib/python3.7/site-packages/django/template/loader.py", line 61, in render_to_string
[Thu Jul 22 08:33:52.856797 2021] [wsgi:error] [pid 11494:tid 140320361740032] [remote 79.183.188.151:52161]     template = get_template(template_name, using=using)
[Thu Jul 22 08:33:52.856838 2021] [wsgi:error] [pid 11494:tid 140320361740032] [remote 79.183.188.151:52161]   File "/mazebolt_project/venv/lib/python3.7/site-packages/django/template/loader.py", line 15, in get_template
[Thu Jul 22 08:33:52.856842 2021] [wsgi:error] [pid 11494:tid 140320361740032] [remote 79.183.188.151:52161]     return engine.get_template(template_name)
[Thu Jul 22 08:33:52.856845 2021] [wsgi:error] [pid 11494:tid 140320361740032] [remote 79.183.188.151:52161]   File "/mazebolt_project/venv/lib/python3.7/site-packages/django/template/backends/django.py", line 34, in get_template
[Thu Jul 22 08:33:52.856849 2021] [wsgi:error] [pid 11494:tid 140320361740032] [remote 79.183.188.151:52161]     return Template(self.engine.get_template(template_name), self)
[Thu Jul 22 08:33:52.856852 2021] [wsgi:error] [pid 11494:tid 140320361740032] [remote 79.183.188.151:52161]   File "/mazebolt_project/venv/lib/python3.7/site-packages/django/template/engine.py", line 143, in get_template
[Thu Jul 22 08:33:52.856856 2021] [wsgi:error] [pid 11494:tid 140320361740032] [remote 79.183.188.151:52161]     template, origin = self.find_template(template_name)
[Thu Jul 22 08:33:52.856861 2021] [wsgi:error] [pid 11494:tid 140320361740032] [remote 79.183.188.151:52161]   File "/mazebolt_project/venv/lib/python3.7/site-packages/django/template/engine.py", line 125, in find_template
[Thu Jul 22 08:33:52.856865 2021] [wsgi:error] [pid 11494:tid 140320361740032] [remote 79.183.188.151:52161]     template = loader.get_template(name, skip=skip)
[Thu Jul 22 08:33:52.856868 2021] [wsgi:error] [pid 11494:tid 140320361740032] [remote 79.183.188.151:52161]   File "/mazebolt_project/venv/lib/python3.7/site-packages/django/template/loaders/base.py", line 30, in get_template
[Thu Jul 22 08:33:52.856871 2021] [wsgi:error] [pid 11494:tid 140320361740032] [remote 79.183.188.151:52161]     contents, origin, origin.template_name, self.engine,
[Thu Jul 22 08:33:52.856874 2021] [wsgi:error] [pid 11494:tid 140320361740032] [remote 79.183.188.151:52161]   File "/mazebolt_project/venv/lib/python3.7/site-packages/django/template/base.py", line 155, in __init__
[Thu Jul 22 08:33:52.856878 2021] [wsgi:error] [pid 11494:tid 140320361740032] [remote 79.183.188.151:52161]     self.nodelist = self.compile_nodelist()
[Thu Jul 22 08:33:52.856881 2021] [wsgi:error] [pid 11494:tid 140320361740032] [remote 79.183.188.151:52161]   File "/mazebolt_project/venv/lib/python3.7/site-packages/django/template/base.py", line 193, in compile_nodelist
[Thu Jul 22 08:33:52.856884 2021] [wsgi:error] [pid 11494:tid 140320361740032] [remote 79.183.188.151:52161]     return parser.parse()
[Thu Jul 22 08:33:52.856887 2021] [wsgi:error] [pid 11494:tid 140320361740032] [remote 79.183.188.151:52161]   File "/mazebolt_project/venv/lib/python3.7/site-packages/django/template/base.py", line 478, in parse
[Thu Jul 22 08:33:52.856890 2021] [wsgi:error] [pid 11494:tid 140320361740032] [remote 79.183.188.151:52161]     raise self.error(token, e)
[Thu Jul 22 08:33:52.856893 2021] [wsgi:error] [pid 11494:tid 140320361740032] [remote 79.183.188.151:52161]   File "/mazebolt_project/venv/lib/python3.7/site-packages/django/template/base.py", line 476, in parse
[Thu Jul 22 08:33:52.856897 2021] [wsgi:error] [pid 11494:tid 140320361740032] [remote 79.183.188.151:52161]     compiled_result = compile_func(self, token)
[Thu Jul 22 08:33:52.856900 2021] [wsgi:error] [pid 11494:tid 140320361740032] [remote 79.183.188.151:52161]   File "/mazebolt_project/venv/lib/python3.7/site-packages/django/template/loader_tags.py", line 278, in do_extends
[Thu Jul 22 08:33:52.856903 2021] [wsgi:error] [pid 11494:tid 140320361740032] [remote 79.183.188.151:52161]     nodelist = parser.parse()
[Thu Jul 22 08:33:52.856906 2021] [wsgi:error] [pid 11494:tid 140320361740032] [remote 79.183.188.151:52161]   File "/mazebolt_project/venv/lib/python3.7/site-packages/django/template/base.py", line 478, in parse
[Thu Jul 22 08:33:52.856923 2021] [wsgi:error] [pid 11494:tid 140320361740032] [remote 79.183.188.151:52161]     raise self.error(token, e)
[Thu Jul 22 08:33:52.856926 2021] [wsgi:error] [pid 11494:tid 140320361740032] [remote 79.183.188.151:52161]   File "/mazebolt_project/venv/lib/python3.7/site-packages/django/template/base.py", line 476, in parse
[Thu Jul 22 08:33:52.856930 2021] [wsgi:error] [pid 11494:tid 140320361740032] [remote 79.183.188.151:52161]     compiled_result = compile_func(self, token)
[Thu Jul 22 08:33:52.856933 2021] [wsgi:error] [pid 11494:tid 140320361740032] [remote 79.183.188.151:52161]   File "/mazebolt_project/venv/lib/python3.7/site-packages/django/template/loader_tags.py", line 216, in do_block
[Thu Jul 22 08:33:52.856936 2021] [wsgi:error] [pid 11494:tid 140320361740032] [remote 79.183.188.151:52161]     nodelist = parser.parse(('endblock',))
[Thu Jul 22 08:33:52.856939 2021] [wsgi:error] [pid 11494:tid 140320361740032] [remote 79.183.188.151:52161]   File "/mazebolt_project/venv/lib/python3.7/site-packages/django/template/base.py", line 478, in parse
[Thu Jul 22 08:33:52.856942 2021] [wsgi:error] [pid 11494:tid 140320361740032] [remote 79.183.188.151:52161]     raise self.error(token, e)
[Thu Jul 22 08:33:52.856945 2021] [wsgi:error] [pid 11494:tid 140320361740032] [remote 79.183.188.151:52161]   File "/mazebolt_project/venv/lib/python3.7/site-packages/django/template/base.py", line 476, in parse
[Thu Jul 22 08:33:52.856949 2021] [wsgi:error] [pid 11494:tid 140320361740032] [remote 79.183.188.151:52161]     compiled_result = compile_func(self, token)
[Thu Jul 22 08:33:52.856952 2021] [wsgi:error] [pid 11494:tid 140320361740032] [remote 79.183.188.151:52161]   File "/mazebolt_project/venv/lib/python3.7/site-packages/django/template/defaulttags.py", line 814, in do_for
[Thu Jul 22 08:33:52.856955 2021] [wsgi:error] [pid 11494:tid 140320361740032] [remote 79.183.188.151:52161]     nodelist_loop = parser.parse(('empty', 'endfor',))
[Thu Jul 22 08:33:52.856958 2021] [wsgi:error] [pid 11494:tid 140320361740032] [remote 79.183.188.151:52161]   File "/mazebolt_project/venv/lib/python3.7/site-packages/django/template/base.py", line 472, in parse
[Thu Jul 22 08:33:52.856961 2021] [wsgi:error] [pid 11494:tid 140320361740032] [remote 79.183.188.151:52161]     self.invalid_block_tag(token, command, parse_until)
[Thu Jul 22 08:33:52.856965 2021] [wsgi:error] [pid 11494:tid 140320361740032] [remote 79.183.188.151:52161]   File "/mazebolt_project/venv/lib/python3.7/site-packages/django/template/base.py", line 528, in invalid_block_tag
[Thu Jul 22 08:33:52.856968 2021] [wsgi:error] [pid 11494:tid 140320361740032] [remote 79.183.188.151:52161]     get_text_list(["'%s'" % p for p in parse_until], 'or'),
[Thu Jul 22 08:33:52.856971 2021] [wsgi:error] [pid 11494:tid 140320361740032] [remote 79.183.188.151:52161] django.template.exceptions.TemplateSyntaxError: Invalid block tag on line 20: 'endblock', expected 'empty' or 'endfor'. Did you forget to register or load this tag?
Exception ignored in: <function BaseEventLoop.__del__ at 0x7f9edad53a60>
Traceback (most recent call last):
  File "/usr/lib/python3.7/asyncio/base_events.py", line 622, in __del__
NameError: name 'ResourceWarning' is not defined
[Thu Jul 22 08:35:57.415579 2021] [wsgi:error] [pid 11587:tid 139756625774336] [remote 79.183.188.151:56603] Internal Server Error: /create_test/
[Thu Jul 22 08:35:57.415632 2021] [wsgi:error] [pid 11587:tid 139756625774336] [remote 79.183.188.151:56603] Traceback (most recent call last):
[Thu Jul 22 08:35:57.415637 2021] [wsgi:error] [pid 11587:tid 139756625774336] [remote 79.183.188.151:56603]   File "/mazebolt_project/venv/lib/python3.7/site-packages/django/core/handlers/exception.py", line 47, in inner
[Thu Jul 22 08:35:57.415641 2021] [wsgi:error] [pid 11587:tid 139756625774336] [remote 79.183.188.151:56603]     response = get_response(request)
[Thu Jul 22 08:35:57.415644 2021] [wsgi:error] [pid 11587:tid 139756625774336] [remote 79.183.188.151:56603]   File "/mazebolt_project/venv/lib/python3.7/site-packages/django/core/handlers/base.py", line 181, in _get_response
[Thu Jul 22 08:35:57.415687 2021] [wsgi:error] [pid 11587:tid 139756625774336] [remote 79.183.188.151:56603]     response = wrapped_callback(request, *callback_args, **callback_kwargs)
[Thu Jul 22 08:35:57.415691 2021] [wsgi:error] [pid 11587:tid 139756625774336] [remote 79.183.188.151:56603]   File "/mazebolt_project/django/mazebolt_project/mazebolt_project/views.py", line 22, in create_test
[Thu Jul 22 08:35:57.415694 2021] [wsgi:error] [pid 11587:tid 139756625774336] [remote 79.183.188.151:56603]     return render(requset, 'create_test.html', selected_instances)
[Thu Jul 22 08:35:57.415697 2021] [wsgi:error] [pid 11587:tid 139756625774336] [remote 79.183.188.151:56603]   File "/mazebolt_project/venv/lib/python3.7/site-packages/django/shortcuts.py", line 19, in render
[Thu Jul 22 08:35:57.415701 2021] [wsgi:error] [pid 11587:tid 139756625774336] [remote 79.183.188.151:56603]     content = loader.render_to_string(template_name, context, request, using=using)
[Thu Jul 22 08:35:57.415704 2021] [wsgi:error] [pid 11587:tid 139756625774336] [remote 79.183.188.151:56603]   File "/mazebolt_project/venv/lib/python3.7/site-packages/django/template/loader.py", line 62, in render_to_string
[Thu Jul 22 08:35:57.415707 2021] [wsgi:error] [pid 11587:tid 139756625774336] [remote 79.183.188.151:56603]     return template.render(context, request)
[Thu Jul 22 08:35:57.415711 2021] [wsgi:error] [pid 11587:tid 139756625774336] [remote 79.183.188.151:56603]   File "/mazebolt_project/venv/lib/python3.7/site-packages/django/template/backends/django.py", line 59, in render
[Thu Jul 22 08:35:57.415714 2021] [wsgi:error] [pid 11587:tid 139756625774336] [remote 79.183.188.151:56603]     context = make_context(context, request, autoescape=self.backend.engine.autoescape)
[Thu Jul 22 08:35:57.415717 2021] [wsgi:error] [pid 11587:tid 139756625774336] [remote 79.183.188.151:56603]   File "/mazebolt_project/venv/lib/python3.7/site-packages/django/template/context.py", line 268, in make_context
[Thu Jul 22 08:35:57.415721 2021] [wsgi:error] [pid 11587:tid 139756625774336] [remote 79.183.188.151:56603]     raise TypeError('context must be a dict rather than %s.' % context.__class__.__name__)
[Thu Jul 22 08:35:57.415724 2021] [wsgi:error] [pid 11587:tid 139756625774336] [remote 79.183.188.151:56603] TypeError: context must be a dict rather than QuerySet.
[Thu Jul 22 09:07:41.919896 2021] [wsgi:error] [pid 11587:tid 139756508186368] [remote 79.183.188.151:60619] Not Found: /instances/
[Thu Jul 22 09:08:02.507575 2021] [wsgi:error] [pid 11587:tid 139756625774336] [remote 79.183.188.151:63256] Not Found: /instance/
[Thu Jul 22 10:03:21.247153 2021] [wsgi:error] [pid 11587:tid 139756508186368] [remote 109.248.6.115:45866] Invalid HTTP_HOST header: 'web-dev.c.mbexam-4.internal'. You may need to add 'web-dev.c.mbexam-4.internal' to ALLOWED_HOSTS.
[Thu Jul 22 10:03:21.275065 2021] [wsgi:error] [pid 11587:tid 139756508186368] [remote 109.248.6.115:45866] Bad Request: /gate.php
[Thu Jul 22 10:11:12.765937 2021] [wsgi:error] [pid 11587:tid 139756625774336] [remote 135.125.217.54:54974] Forbidden (CSRF cookie not set.): /
[Thu Jul 22 10:11:12.815599 2021] [wsgi:error] [pid 11587:tid 139756508186368] [remote 135.125.217.54:55060] Not Found: /.env
Exception ignored in: <function BaseEventLoop.__del__ at 0x7f1b980cda60>
Traceback (most recent call last):
  File "/usr/lib/python3.7/asyncio/base_events.py", line 622, in __del__
NameError: name 'ResourceWarning' is not defined
[Thu Jul 22 10:18:31.647780 2021] [wsgi:error] [pid 12010:tid 140303527614208] [remote 209.141.41.98:32880] Not Found: /boaform/admin/formLogin
Exception ignored in: <function BaseEventLoop.__del__ at 0x7f9af472ba60>
Traceback (most recent call last):
  File "/usr/lib/python3.7/asyncio/base_events.py", line 622, in __del__
NameError: name 'ResourceWarning' is not defined
[Thu Jul 22 10:36:13.858043 2021] [wsgi:error] [pid 12112:tid 139727191631616] [remote 79.183.188.151:55686] Internal Server Error: /
[Thu Jul 22 10:36:13.858114 2021] [wsgi:error] [pid 12112:tid 139727191631616] [remote 79.183.188.151:55686] Traceback (most recent call last):
[Thu Jul 22 10:36:13.858151 2021] [wsgi:error] [pid 12112:tid 139727191631616] [remote 79.183.188.151:55686]   File "/mazebolt_project/venv/lib/python3.7/site-packages/django/core/handlers/exception.py", line 47, in inner
[Thu Jul 22 10:36:13.858155 2021] [wsgi:error] [pid 12112:tid 139727191631616] [remote 79.183.188.151:55686]     response = get_response(request)
[Thu Jul 22 10:36:13.858158 2021] [wsgi:error] [pid 12112:tid 139727191631616] [remote 79.183.188.151:55686]   File "/mazebolt_project/venv/lib/python3.7/site-packages/django/core/handlers/base.py", line 181, in _get_response
[Thu Jul 22 10:36:13.858162 2021] [wsgi:error] [pid 12112:tid 139727191631616] [remote 79.183.188.151:55686]     response = wrapped_callback(request, *callback_args, **callback_kwargs)
[Thu Jul 22 10:36:13.858166 2021] [wsgi:error] [pid 12112:tid 139727191631616] [remote 79.183.188.151:55686]   File "/mazebolt_project/django/mazebolt_project/mazebolt_project/views.py", line 14, in instance
[Thu Jul 22 10:36:13.858169 2021] [wsgi:error] [pid 12112:tid 139727191631616] [remote 79.183.188.151:55686]     with open('debugfile.txt', 'w') as f:
[Thu Jul 22 10:36:13.858172 2021] [wsgi:error] [pid 12112:tid 139727191631616] [remote 79.183.188.151:55686] PermissionError: [Errno 13] Permission denied: 'debugfile.txt'
Exception ignored in: <function BaseEventLoop.__del__ at 0x7f14c4a5da60>
Traceback (most recent call last):
  File "/usr/lib/python3.7/asyncio/base_events.py", line 622, in __del__
NameError: name 'ResourceWarning' is not defined
[Thu Jul 22 10:43:43.250608 2021] [wsgi:error] [pid 12207:tid 139653796624128] [remote 79.183.188.151:51217] Internal Server Error: /
[Thu Jul 22 10:43:43.250662 2021] [wsgi:error] [pid 12207:tid 139653796624128] [remote 79.183.188.151:51217] Traceback (most recent call last):
[Thu Jul 22 10:43:43.250667 2021] [wsgi:error] [pid 12207:tid 139653796624128] [remote 79.183.188.151:51217]   File "/mazebolt_project/venv/lib/python3.7/site-packages/django/core/handlers/exception.py", line 47, in inner
[Thu Jul 22 10:43:43.250672 2021] [wsgi:error] [pid 12207:tid 139653796624128] [remote 79.183.188.151:51217]     response = get_response(request)
[Thu Jul 22 10:43:43.250675 2021] [wsgi:error] [pid 12207:tid 139653796624128] [remote 79.183.188.151:51217]   File "/mazebolt_project/venv/lib/python3.7/site-packages/django/core/handlers/base.py", line 181, in _get_response
[Thu Jul 22 10:43:43.250679 2021] [wsgi:error] [pid 12207:tid 139653796624128] [remote 79.183.188.151:51217]     response = wrapped_callback(request, *callback_args, **callback_kwargs)
[Thu Jul 22 10:43:43.250683 2021] [wsgi:error] [pid 12207:tid 139653796624128] [remote 79.183.188.151:51217]   File "/mazebolt_project/django/mazebolt_project/mazebolt_project/views.py", line 17, in instance
[Thu Jul 22 10:43:43.250687 2021] [wsgi:error] [pid 12207:tid 139653796624128] [remote 79.183.188.151:51217]     with open('debugfile.txt', 'w') as f:
[Thu Jul 22 10:43:43.250691 2021] [wsgi:error] [pid 12207:tid 139653796624128] [remote 79.183.188.151:51217] PermissionError: [Errno 13] Permission denied: 'debugfile.txt'
[Thu Jul 22 10:43:50.020403 2021] [wsgi:error] [pid 12207:tid 139653847013120] [remote 79.183.188.151:60600] Internal Server Error: /
[Thu Jul 22 10:43:50.020449 2021] [wsgi:error] [pid 12207:tid 139653847013120] [remote 79.183.188.151:60600] Traceback (most recent call last):
[Thu Jul 22 10:43:50.020454 2021] [wsgi:error] [pid 12207:tid 139653847013120] [remote 79.183.188.151:60600]   File "/mazebolt_project/venv/lib/python3.7/site-packages/django/core/handlers/exception.py", line 47, in inner
[Thu Jul 22 10:43:50.020458 2021] [wsgi:error] [pid 12207:tid 139653847013120] [remote 79.183.188.151:60600]     response = get_response(request)
[Thu Jul 22 10:43:50.020462 2021] [wsgi:error] [pid 12207:tid 139653847013120] [remote 79.183.188.151:60600]   File "/mazebolt_project/venv/lib/python3.7/site-packages/django/core/handlers/base.py", line 181, in _get_response
[Thu Jul 22 10:43:50.020491 2021] [wsgi:error] [pid 12207:tid 139653847013120] [remote 79.183.188.151:60600]     response = wrapped_callback(request, *callback_args, **callback_kwargs)
[Thu Jul 22 10:43:50.020494 2021] [wsgi:error] [pid 12207:tid 139653847013120] [remote 79.183.188.151:60600]   File "/mazebolt_project/django/mazebolt_project/mazebolt_project/views.py", line 17, in instance
[Thu Jul 22 10:43:50.020498 2021] [wsgi:error] [pid 12207:tid 139653847013120] [remote 79.183.188.151:60600]     with open('debugfile.txt', 'w') as f:
[Thu Jul 22 10:43:50.020501 2021] [wsgi:error] [pid 12207:tid 139653847013120] [remote 79.183.188.151:60600] PermissionError: [Errno 13] Permission denied: 'debugfile.txt'
[Thu Jul 22 10:43:54.274461 2021] [wsgi:error] [pid 12207:tid 139653796624128] [remote 79.183.188.151:51110] Internal Server Error: /
[Thu Jul 22 10:43:54.274545 2021] [wsgi:error] [pid 12207:tid 139653796624128] [remote 79.183.188.151:51110] Traceback (most recent call last):
[Thu Jul 22 10:43:54.274549 2021] [wsgi:error] [pid 12207:tid 139653796624128] [remote 79.183.188.151:51110]   File "/mazebolt_project/venv/lib/python3.7/site-packages/django/core/handlers/exception.py", line 47, in inner
[Thu Jul 22 10:43:54.274553 2021] [wsgi:error] [pid 12207:tid 139653796624128] [remote 79.183.188.151:51110]     response = get_response(request)
[Thu Jul 22 10:43:54.274556 2021] [wsgi:error] [pid 12207:tid 139653796624128] [remote 79.183.188.151:51110]   File "/mazebolt_project/venv/lib/python3.7/site-packages/django/core/handlers/base.py", line 181, in _get_response
[Thu Jul 22 10:43:54.274560 2021] [wsgi:error] [pid 12207:tid 139653796624128] [remote 79.183.188.151:51110]     response = wrapped_callback(request, *callback_args, **callback_kwargs)
[Thu Jul 22 10:43:54.274563 2021] [wsgi:error] [pid 12207:tid 139653796624128] [remote 79.183.188.151:51110]   File "/mazebolt_project/django/mazebolt_project/mazebolt_project/views.py", line 17, in instance
[Thu Jul 22 10:43:54.274567 2021] [wsgi:error] [pid 12207:tid 139653796624128] [remote 79.183.188.151:51110]     with open('debugfile.txt', 'w') as f:
[Thu Jul 22 10:43:54.274570 2021] [wsgi:error] [pid 12207:tid 139653796624128] [remote 79.183.188.151:51110] PermissionError: [Errno 13] Permission denied: 'debugfile.txt'
[Thu Jul 22 10:44:46.819571 2021] [wsgi:error] [pid 12207:tid 139653847013120] [remote 79.183.188.151:62342] Internal Server Error: /
[Thu Jul 22 10:44:46.819624 2021] [wsgi:error] [pid 12207:tid 139653847013120] [remote 79.183.188.151:62342] Traceback (most recent call last):
[Thu Jul 22 10:44:46.819629 2021] [wsgi:error] [pid 12207:tid 139653847013120] [remote 79.183.188.151:62342]   File "/mazebolt_project/venv/lib/python3.7/site-packages/django/core/handlers/exception.py", line 47, in inner
[Thu Jul 22 10:44:46.819634 2021] [wsgi:error] [pid 12207:tid 139653847013120] [remote 79.183.188.151:62342]     response = get_response(request)
[Thu Jul 22 10:44:46.819638 2021] [wsgi:error] [pid 12207:tid 139653847013120] [remote 79.183.188.151:62342]   File "/mazebolt_project/venv/lib/python3.7/site-packages/django/core/handlers/base.py", line 181, in _get_response
[Thu Jul 22 10:44:46.819643 2021] [wsgi:error] [pid 12207:tid 139653847013120] [remote 79.183.188.151:62342]     response = wrapped_callback(request, *callback_args, **callback_kwargs)
[Thu Jul 22 10:44:46.819647 2021] [wsgi:error] [pid 12207:tid 139653847013120] [remote 79.183.188.151:62342]   File "/mazebolt_project/django/mazebolt_project/mazebolt_project/views.py", line 17, in instance
[Thu Jul 22 10:44:46.819651 2021] [wsgi:error] [pid 12207:tid 139653847013120] [remote 79.183.188.151:62342]     with open('debugfile.txt', 'w') as f:
[Thu Jul 22 10:44:46.819656 2021] [wsgi:error] [pid 12207:tid 139653847013120] [remote 79.183.188.151:62342] PermissionError: [Errno 13] Permission denied: 'debugfile.txt'
[Thu Jul 22 10:44:53.565595 2021] [wsgi:error] [pid 12207:tid 139653847013120] [remote 79.183.188.151:65172] Internal Server Error: /
[Thu Jul 22 10:44:53.565636 2021] [wsgi:error] [pid 12207:tid 139653847013120] [remote 79.183.188.151:65172] Traceback (most recent call last):
[Thu Jul 22 10:44:53.565655 2021] [wsgi:error] [pid 12207:tid 139653847013120] [remote 79.183.188.151:65172]   File "/mazebolt_project/venv/lib/python3.7/site-packages/django/core/handlers/exception.py", line 47, in inner
[Thu Jul 22 10:44:53.565660 2021] [wsgi:error] [pid 12207:tid 139653847013120] [remote 79.183.188.151:65172]     response = get_response(request)
[Thu Jul 22 10:44:53.565663 2021] [wsgi:error] [pid 12207:tid 139653847013120] [remote 79.183.188.151:65172]   File "/mazebolt_project/venv/lib/python3.7/site-packages/django/core/handlers/base.py", line 181, in _get_response
[Thu Jul 22 10:44:53.565666 2021] [wsgi:error] [pid 12207:tid 139653847013120] [remote 79.183.188.151:65172]     response = wrapped_callback(request, *callback_args, **callback_kwargs)
[Thu Jul 22 10:44:53.565670 2021] [wsgi:error] [pid 12207:tid 139653847013120] [remote 79.183.188.151:65172]   File "/mazebolt_project/django/mazebolt_project/mazebolt_project/views.py", line 17, in instance
[Thu Jul 22 10:44:53.565673 2021] [wsgi:error] [pid 12207:tid 139653847013120] [remote 79.183.188.151:65172]     with open('debugfile.txt', 'w') as f:
[Thu Jul 22 10:44:53.565676 2021] [wsgi:error] [pid 12207:tid 139653847013120] [remote 79.183.188.151:65172] PermissionError: [Errno 13] Permission denied: 'debugfile.txt'
[Thu Jul 22 10:47:41.815168 2021] [wsgi:error] [pid 12207:tid 139653847013120] [remote 79.183.188.151:62689] Internal Server Error: /create_test
[Thu Jul 22 10:47:41.815218 2021] [wsgi:error] [pid 12207:tid 139653847013120] [remote 79.183.188.151:62689] Traceback (most recent call last):
[Thu Jul 22 10:47:41.815222 2021] [wsgi:error] [pid 12207:tid 139653847013120] [remote 79.183.188.151:62689]   File "/mazebolt_project/venv/lib/python3.7/site-packages/django/core/handlers/exception.py", line 47, in inner
[Thu Jul 22 10:47:41.815226 2021] [wsgi:error] [pid 12207:tid 139653847013120] [remote 79.183.188.151:62689]     response = get_response(request)
[Thu Jul 22 10:47:41.815230 2021] [wsgi:error] [pid 12207:tid 139653847013120] [remote 79.183.188.151:62689]   File "/mazebolt_project/venv/lib/python3.7/site-packages/django/utils/deprecation.py", line 116, in __call__
[Thu Jul 22 10:47:41.815234 2021] [wsgi:error] [pid 12207:tid 139653847013120] [remote 79.183.188.151:62689]     response = self.process_request(request)
[Thu Jul 22 10:47:41.815238 2021] [wsgi:error] [pid 12207:tid 139653847013120] [remote 79.183.188.151:62689]   File "/mazebolt_project/venv/lib/python3.7/site-packages/django/middleware/common.py", line 54, in process_request
[Thu Jul 22 10:47:41.815242 2021] [wsgi:error] [pid 12207:tid 139653847013120] [remote 79.183.188.151:62689]     path = self.get_full_path_with_slash(request)
[Thu Jul 22 10:47:41.815245 2021] [wsgi:error] [pid 12207:tid 139653847013120] [remote 79.183.188.151:62689]   File "/mazebolt_project/venv/lib/python3.7/site-packages/django/middleware/common.py", line 95, in get_full_path_with_slash
[Thu Jul 22 10:47:41.815249 2021] [wsgi:error] [pid 12207:tid 139653847013120] [remote 79.183.188.151:62689]     'url': request.get_host() + new_path,
[Thu Jul 22 10:47:41.815253 2021] [wsgi:error] [pid 12207:tid 139653847013120] [remote 79.183.188.151:62689] RuntimeError: You called this URL via POST, but the URL doesn't end in a slash and you have APPEND_SLASH set. Django can't redirect to the slash URL while maintaining POST data. Change your form to point to 34.89.53.68/create_test/ (note the trailing slash), or set APPEND_SLASH=False in your Django settings.
Exception ignored in: <function BaseEventLoop.__del__ at 0x7f03aa757a60>
Traceback (most recent call last):
  File "/usr/lib/python3.7/asyncio/base_events.py", line 622, in __del__
NameError: name 'ResourceWarning' is not defined
[Thu Jul 22 10:52:52.511675 2021] [wsgi:error] [pid 12320:tid 140660112156416] [remote 79.183.188.151:52102] Internal Server Error: /create_test
[Thu Jul 22 10:52:52.511729 2021] [wsgi:error] [pid 12320:tid 140660112156416] [remote 79.183.188.151:52102] Traceback (most recent call last):
[Thu Jul 22 10:52:52.511775 2021] [wsgi:error] [pid 12320:tid 140660112156416] [remote 79.183.188.151:52102]   File "/mazebolt_project/venv/lib/python3.7/site-packages/django/core/handlers/exception.py", line 47, in inner
[Thu Jul 22 10:52:52.511779 2021] [wsgi:error] [pid 12320:tid 140660112156416] [remote 79.183.188.151:52102]     response = get_response(request)
[Thu Jul 22 10:52:52.511782 2021] [wsgi:error] [pid 12320:tid 140660112156416] [remote 79.183.188.151:52102]   File "/mazebolt_project/venv/lib/python3.7/site-packages/django/utils/deprecation.py", line 116, in __call__
[Thu Jul 22 10:52:52.511786 2021] [wsgi:error] [pid 12320:tid 140660112156416] [remote 79.183.188.151:52102]     response = self.process_request(request)
[Thu Jul 22 10:52:52.511789 2021] [wsgi:error] [pid 12320:tid 140660112156416] [remote 79.183.188.151:52102]   File "/mazebolt_project/venv/lib/python3.7/site-packages/django/middleware/common.py", line 54, in process_request
[Thu Jul 22 10:52:52.511793 2021] [wsgi:error] [pid 12320:tid 140660112156416] [remote 79.183.188.151:52102]     path = self.get_full_path_with_slash(request)
[Thu Jul 22 10:52:52.511796 2021] [wsgi:error] [pid 12320:tid 140660112156416] [remote 79.183.188.151:52102]   File "/mazebolt_project/venv/lib/python3.7/site-packages/django/middleware/common.py", line 95, in get_full_path_with_slash
[Thu Jul 22 10:52:52.511800 2021] [wsgi:error] [pid 12320:tid 140660112156416] [remote 79.183.188.151:52102]     'url': request.get_host() + new_path,
[Thu Jul 22 10:52:52.511804 2021] [wsgi:error] [pid 12320:tid 140660112156416] [remote 79.183.188.151:52102] RuntimeError: You called this URL via POST, but the URL doesn't end in a slash and you have APPEND_SLASH set. Django can't redirect to the slash URL while maintaining POST data. Change your form to point to 34.89.53.68/create_test/ (note the trailing slash), or set APPEND_SLASH=False in your Django settings.
[Thu Jul 22 10:53:11.895265 2021] [wsgi:error] [pid 12320:tid 140660112156416] [remote 79.183.188.151:64876] Internal Server Error: /create_test
[Thu Jul 22 10:53:11.895329 2021] [wsgi:error] [pid 12320:tid 140660112156416] [remote 79.183.188.151:64876] Traceback (most recent call last):
[Thu Jul 22 10:53:11.895335 2021] [wsgi:error] [pid 12320:tid 140660112156416] [remote 79.183.188.151:64876]   File "/mazebolt_project/venv/lib/python3.7/site-packages/django/core/handlers/exception.py", line 47, in inner
[Thu Jul 22 10:53:11.895339 2021] [wsgi:error] [pid 12320:tid 140660112156416] [remote 79.183.188.151:64876]     response = get_response(request)
[Thu Jul 22 10:53:11.895343 2021] [wsgi:error] [pid 12320:tid 140660112156416] [remote 79.183.188.151:64876]   File "/mazebolt_project/venv/lib/python3.7/site-packages/django/utils/deprecation.py", line 116, in __call__
[Thu Jul 22 10:53:11.895347 2021] [wsgi:error] [pid 12320:tid 140660112156416] [remote 79.183.188.151:64876]     response = self.process_request(request)
[Thu Jul 22 10:53:11.895351 2021] [wsgi:error] [pid 12320:tid 140660112156416] [remote 79.183.188.151:64876]   File "/mazebolt_project/venv/lib/python3.7/site-packages/django/middleware/common.py", line 54, in process_request
[Thu Jul 22 10:53:11.895355 2021] [wsgi:error] [pid 12320:tid 140660112156416] [remote 79.183.188.151:64876]     path = self.get_full_path_with_slash(request)
[Thu Jul 22 10:53:11.895359 2021] [wsgi:error] [pid 12320:tid 140660112156416] [remote 79.183.188.151:64876]   File "/mazebolt_project/venv/lib/python3.7/site-packages/django/middleware/common.py", line 95, in get_full_path_with_slash
[Thu Jul 22 10:53:11.895363 2021] [wsgi:error] [pid 12320:tid 140660112156416] [remote 79.183.188.151:64876]     'url': request.get_host() + new_path,
[Thu Jul 22 10:53:11.895368 2021] [wsgi:error] [pid 12320:tid 140660112156416] [remote 79.183.188.151:64876] RuntimeError: You called this URL via POST, but the URL doesn't end in a slash and you have APPEND_SLASH set. Django can't redirect to the slash URL while maintaining POST data. Change your form to point to 34.89.53.68/create_test/ (note the trailing slash), or set APPEND_SLASH=False in your Django settings.
sh: 1: cannot create debugfile.txt: Permission denied
Exception ignored in: <function BaseEventLoop.__del__ at 0x7fa25ba89a60>
Traceback (most recent call last):
  File "/usr/lib/python3.7/asyncio/base_events.py", line 622, in __del__
NameError: name 'ResourceWarning' is not defined
Exception ignored in: <function BaseEventLoop.__del__ at 0x7f52df710a60>
Traceback (most recent call last):
  File "/usr/lib/python3.7/asyncio/base_events.py", line 622, in __del__
NameError: name 'ResourceWarning' is not defined
[Fri Jul 23 08:44:39.536801 2021] [wsgi:error] [pid 16703:tid 140334893975296] [remote 79.183.188.151:65532] !!!!!!!!!!!! /mazebolt_project/django/mazebolt_project/mazebolt_project
[Fri Jul 23 08:47:08.488307 2021] [wsgi:error] [pid 16703:tid 140334893975296] [remote 79.183.188.151:54009] dict_keys(['start', 'csrfmiddlewaretoken', 'mbexam-8c77c0c8-74c3-461f-8839-4a9181f276dc'])
[Fri Jul 23 08:53:11.953803 2021] [wsgi:error] [pid 16703:tid 140334893975296] [remote 79.183.188.151:62661] 3
[Fri Jul 23 08:53:11.953964 2021] [wsgi:error] [pid 16703:tid 140334893975296] [remote 79.183.188.151:62661] Creating mbexam-7bcfc29f-b9c1-463b-b480-ea156c094506
[Fri Jul 23 08:53:14.082412 2021] [wsgi:error] [pid 16703:tid 140334893975296] [remote 79.183.188.151:62661] Operation Result Create: {'id': '8252843438426766742', 'name': 'operation-1627030392271-5c7c68891f0a1-701f88c5-09c6d9cd', 'zone': 'https://www.googleapis.com/compute/v1/projects/mbexam-4/zones/europe-west1-b', 'operationType': 'insert', 'targetLink': 'https://www.googleapis.com/compute/v1/projects/mbexam-4/zones/europe-west1-b/instances/mbexam-7bcfc29f-b9c1-463b-b480-ea156c094506', 'targetId': '2790083764529085847', 'status': 'RUNNING', 'user': 'mb-exam-4@mbexam-4.iam.gserviceaccount.com', 'progress': 0, 'insertTime': '2021-07-23T01:53:13.883-07:00', 'startTime': '2021-07-23T01:53:13.884-07:00', 'selfLink': 'https://www.googleapis.com/compute/v1/projects/mbexam-4/zones/europe-west1-b/operations/operation-1627030392271-5c7c68891f0a1-701f88c5-09c6d9cd', 'kind': 'compute#operation'}
[Fri Jul 23 08:53:14.092000 2021] [wsgi:error] [pid 16703:tid 140334893975296] [remote 79.183.188.151:62661] Creating mbexam-06deb20a-71f1-4560-825c-441f0154dca8
[Fri Jul 23 08:53:16.127224 2021] [wsgi:error] [pid 16703:tid 140334893975296] [remote 79.183.188.151:62661] Operation Result Create: {'id': '6121179069805968788', 'name': 'operation-1627030394210-5c7c688af87d2-cb11667c-eab15c6a', 'zone': 'https://www.googleapis.com/compute/v1/projects/mbexam-4/zones/europe-west1-b', 'operationType': 'insert', 'targetLink': 'https://www.googleapis.com/compute/v1/projects/mbexam-4/zones/europe-west1-b/instances/mbexam-06deb20a-71f1-4560-825c-441f0154dca8', 'targetId': '9038094478112931221', 'status': 'RUNNING', 'user': 'mb-exam-4@mbexam-4.iam.gserviceaccount.com', 'progress': 0, 'insertTime': '2021-07-23T01:53:15.917-07:00', 'startTime': '2021-07-23T01:53:15.917-07:00', 'selfLink': 'https://www.googleapis.com/compute/v1/projects/mbexam-4/zones/europe-west1-b/operations/operation-1627030394210-5c7c688af87d2-cb11667c-eab15c6a', 'kind': 'compute#operation'}
[Fri Jul 23 08:53:16.137280 2021] [wsgi:error] [pid 16703:tid 140334893975296] [remote 79.183.188.151:62661] Creating mbexam-6991e521-35a3-44f1-bd97-e41169029e86
[Fri Jul 23 08:53:17.519275 2021] [wsgi:error] [pid 16703:tid 140334893975296] [remote 79.183.188.151:62661] Operation Result Create: {'id': '7293143016294268306', 'name': 'operation-1627030396259-5c7c688cecb83-620eca09-63c7ffd2', 'zone': 'https://www.googleapis.com/compute/v1/projects/mbexam-4/zones/europe-west1-b', 'operationType': 'insert', 'targetLink': 'https://www.googleapis.com/compute/v1/projects/mbexam-4/zones/europe-west1-b/instances/mbexam-6991e521-35a3-44f1-bd97-e41169029e86', 'targetId': '1387603915332599187', 'status': 'RUNNING', 'user': 'mb-exam-4@mbexam-4.iam.gserviceaccount.com', 'progress': 0, 'insertTime': '2021-07-23T01:53:17.316-07:00', 'startTime': '2021-07-23T01:53:17.316-07:00', 'selfLink': 'https://www.googleapis.com/compute/v1/projects/mbexam-4/zones/europe-west1-b/operations/operation-1627030396259-5c7c688cecb83-620eca09-63c7ffd2', 'kind': 'compute#operation'}
[Fri Jul 23 09:12:08.598302 2021] [wsgi:error] [pid 16703:tid 140334776379136] [remote 79.183.188.151:50640] dict_keys(['start', 'csrfmiddlewaretoken', 'mbexam-06deb20a-71f1-4560-825c-441f0154dca8', 'mbexam-6991e521-35a3-44f1-bd97-e41169029e86'])
[Fri Jul 23 09:12:12.592571 2021] [wsgi:error] [pid 16703:tid 140334776379136] [remote 109.226.50.4:42318] Internal Server Error: /tests/
[Fri Jul 23 09:12:12.592612 2021] [wsgi:error] [pid 16703:tid 140334776379136] [remote 109.226.50.4:42318] Traceback (most recent call last):
[Fri Jul 23 09:12:12.592617 2021] [wsgi:error] [pid 16703:tid 140334776379136] [remote 109.226.50.4:42318]   File "/mazebolt_project/venv/lib/python3.7/site-packages/django/core/handlers/exception.py", line 47, in inner
[Fri Jul 23 09:12:12.592622 2021] [wsgi:error] [pid 16703:tid 140334776379136] [remote 109.226.50.4:42318]     response = get_response(request)
[Fri Jul 23 09:12:12.592625 2021] [wsgi:error] [pid 16703:tid 140334776379136] [remote 109.226.50.4:42318]   File "/mazebolt_project/venv/lib/python3.7/site-packages/django/core/handlers/base.py", line 188, in _get_response
[Fri Jul 23 09:12:12.592629 2021] [wsgi:error] [pid 16703:tid 140334776379136] [remote 109.226.50.4:42318]     self.check_response(response, callback)
[Fri Jul 23 09:12:12.592633 2021] [wsgi:error] [pid 16703:tid 140334776379136] [remote 109.226.50.4:42318]   File "/mazebolt_project/venv/lib/python3.7/site-packages/django/core/handlers/base.py", line 311, in check_response
[Fri Jul 23 09:12:12.592637 2021] [wsgi:error] [pid 16703:tid 140334776379136] [remote 109.226.50.4:42318]     "instead." % name
[Fri Jul 23 09:12:12.592640 2021] [wsgi:error] [pid 16703:tid 140334776379136] [remote 109.226.50.4:42318] ValueError: The view mazebolt_project.views.test didn't return an HttpResponse object. It returned None instead.
[Fri Jul 23 10:07:24.479166 2021] [wsgi:error] [pid 16703:tid 140334893975296] [remote 135.125.217.54:54570] Forbidden (CSRF cookie not set.): /
[Fri Jul 23 10:07:24.535357 2021] [wsgi:error] [pid 16703:tid 140334776379136] [remote 135.125.217.54:54628] Not Found: /.env
[Fri Jul 23 10:13:34.791386 2021] [wsgi:error] [pid 16703:tid 140334893975296] [remote 123.5.144.90:42046] Not Found: /boaform/admin/formLogin
[Fri Jul 23 10:26:28.330124 2021] [wsgi:error] [pid 16703:tid 140334776379136] [remote 209.141.41.98:47222] Not Found: /boaform/admin/formLogin
[Fri Jul 23 14:30:50.671407 2021] [wsgi:error] [pid 16703:tid 140334893975296] [remote 109.67.137.53:52158] dict_keys(['start', 'csrfmiddlewaretoken', 'mbexam-6991e521-35a3-44f1-bd97-e41169029e86', 'mbexam-7bcfc29f-b9c1-463b-b480-ea156c094506'])
[Fri Jul 23 14:46:26.279675 2021] [wsgi:error] [pid 16703:tid 140334776379136] [remote 18.207.192.16:62682] Not Found: /clientaccesspolicy.xml
[Fri Jul 23 14:53:54.667779 2021] [wsgi:error] [pid 16703:tid 140334776379136] [remote 109.67.137.53:54374] dict_keys(['start', 'csrfmiddlewaretoken', 'mbexam-6991e521-35a3-44f1-bd97-e41169029e86', 'mbexam-7bcfc29f-b9c1-463b-b480-ea156c094506'])
[Fri Jul 23 14:54:55.433342 2021] [wsgi:error] [pid 16703:tid 140334893975296] [remote 109.67.137.53:56131] dict_keys(['start', 'csrfmiddlewaretoken', 'mbexam-6991e521-35a3-44f1-bd97-e41169029e86', 'mbexam-7bcfc29f-b9c1-463b-b480-ea156c094506'])
[Fri Jul 23 14:59:24.149662 2021] [wsgi:error] [pid 16703:tid 140334776379136] [remote 109.67.137.53:57365] dict_keys(['start', 'csrfmiddlewaretoken', 'mbexam-6991e521-35a3-44f1-bd97-e41169029e86', 'mbexam-7bcfc29f-b9c1-463b-b480-ea156c094506'])
[Fri Jul 23 15:02:03.602242 2021] [wsgi:error] [pid 16703:tid 140334893975296] [remote 109.67.137.53:61063] dict_keys(['start', 'csrfmiddlewaretoken', 'mbexam-06deb20a-71f1-4560-825c-441f0154dca8'])
Exception ignored in: <function BaseEventLoop.__del__ at 0x7fa23b857a60>
Traceback (most recent call last):
  File "/usr/lib/python3.7/asyncio/base_events.py", line 622, in __del__
NameError: name 'ResourceWarning' is not defined
Exception ignored in: <generator object path at 0x7fa239aeac00>
Traceback (most recent call last):
  File "/usr/lib/python3.7/importlib/resources.py", line 190, in path
NameError: name 'FileNotFoundError' is not defined
[Sat Jul 24 01:22:35.356495 2021] [wsgi:error] [pid 20407:tid 139624663271168] [remote 109.67.76.226:60180] !!!!!!!!!!!! /mazebolt_project/django/mazebolt_project/mazebolt_project
[Sat Jul 24 04:18:51.569626 2021] [wsgi:error] [pid 20407:tid 139624663271168] [remote 185.142.236.43:55346] Not Found: /robots.txt
[Sat Jul 24 04:18:51.905496 2021] [wsgi:error] [pid 20407:tid 139624621258496] [remote 185.142.236.43:55628] Not Found: /sitemap.xml
[Sat Jul 24 04:19:06.414281 2021] [wsgi:error] [pid 20407:tid 139624663271168] [remote 185.142.236.43:38794] Not Found: /.well-known/security.txt
[Sat Jul 24 04:48:59.698177 2021] [wsgi:error] [pid 20407:tid 139624621258496] [remote 116.75.193.249:42723] Not Found: /GponForm/diag_Form
[Sat Jul 24 04:56:18.056592 2021] [wsgi:error] [pid 20407:tid 139624621258496] [remote 109.67.76.226:63154] Not Found: /favicon.ico
